[{"link": "https://stackoverflow.com/questions/53588155/the-truth-value-of-a-series-is-ambiguous-use-a-empty-a-bool-a-item-a-any", "error": "ValueError                                Traceback (most recent call last)\n<ipython-input-922-9fe360350b03> in <module>()\n----> 1 print(ph_convert(time,we,h,a,w))\n\n<ipython-input-904-73455dabb050> in ph_convert(time, we, h, a, w)\n      3    \n----> 5         while time <= 30:\n      6             level = 1.1\n      7             level = float(level)\n\n~\\Anaconda3\\lib\\site-packages\\pandas\\core\\generic.py in __nonzero__(self)\n   1571         raise ValueError(\"The truth value of a {0} is ambiguous. \"\n   1572                          \"Use a.empty, a.bool(), a.item(), a.any() or a.all().\"\n-> 1573                          .format(self.__class__.__name__))\n   1574 \n   1575     __bool__ = __nonzero__\n\nValueError: The truth value of a Series is ambiguous. Use a.empty, a.bool(), a.item(), a.any() or a.all().\n"}, {"link": "https://stackoverflow.com/questions/33697263/python-snap7-windows-cant-find-snap7-library", "error": " >>> \nTraceback (most recent call last):\n  File \"Y:\\Lonnox\\Projekte\\Bibliothek\\Python und SPS\\S7-1200 Test.py\", line 6, in <module>\n    plc = snap7.client.Client()\n  File \"C:\\Python34\\lib\\site-packages\\snap7\\client.py\", line 30, in __init__\n    self.library = load_library()\n  File \"C:\\Python34\\lib\\site-packages\\snap7\\common.py\", line 54, in load_library\n    return Snap7Library(lib_location).cdll\n  File \"C:\\Python34\\lib\\site-packages\\snap7\\common.py\", line 46, in __init__\n    raise Snap7Exception(msg)\nsnap7.snap7exceptions.Snap7Exception: can't find snap7 library. If installed, try running ldconfig\n"}, {"link": "https://stackoverflow.com/questions/63329657/python-3-7-error-unsupported-pickle-protocol-5", "error": "config = pickle.load(open(f\"{path}/params.pkl\", \"rb\"))\n\n---------------------------------------------------------------------------\nValueError                                Traceback (most recent call last)\n<ipython-input-28-c964561b863c> in <module>\n----> 1 config = pickle.load(open(f\"{path}/params.pkl\", \"rb\"))\n\nValueError: unsupported pickle protocol: 5\n\n"}, {"link": "https://stackoverflow.com/questions/67771207/how-to-fix-relative-import-error-in-python-without-code-change", "error": "> python test_module.py\nTraceback (most recent call last):\n  File \"test_module.py\", line 4, in <module>\n    from . import module\nImportError: attempted relative import with no known parent package\n"}, {"link": "https://stackoverflow.com/questions/66199655/python-unit-test-nameerror-name-upper-is-not-defined", "error": "D:\\\u0414\u043e\u0445\u0443\u044f \u043f\u0440\u043e\u0433\u0440\u0430\u043c\u043c\u0438\u0441\u0442\\Projects>python test_upper.py\nE\n======================================================================\nERROR: test_one_word (__main__.TestUpper)\n----------------------------------------------------------------------\nTraceback (most recent call last):\n  File \"test_upper.py\", line 9, in test_one_word\n    result = upper.upper_text(text)\nNameError: name 'upper' is not defined\n\n----------------------------------------------------------------------\nRan 1 test in 0.001s\n\nFAILED (errors=1)\n"}, {"link": "https://stackoverflow.com/questions/53175387/sympy-left-sided-limit-of-sign-function", "error": "TypeError                                 Traceback (most recent call last)\n<ipython-input-31-56b1fd6b589d> in <module>()\n      1 x = sp.Symbol('x')\n      2 f = sp.sign(sp.cos(sp.pi/x))\n----> 3 sp.limit(f, x, 2, '-')\n~\\Anaconda3\\lib\\site-packages\\sympy\\series\\limits.py in limit(e, z, z0, dir)\n     47     \"\"\"\n     48 \n---> 49     return Limit(e, z, z0, dir).doit(deep=False)\n     50 \n     51 \n~\\Anaconda3\\lib\\site-packages\\sympy\\series\\limits.py in doit(self, **hints)\n    178 \n    179         try:\n--> 180             r = gruntz(e, z, z0, dir)\n    181             if r is S.NaN:\n    182                 raise PoleError()\n~\\Anaconda3\\lib\\site-packages\\sympy\\series\\gruntz.py in gruntz(e, z, z0, dir)\n    656         else:\n    657             raise NotImplementedError(\"dir must be '+' or '-'\")\n--> 658         r = limitinf(e0, z)\n    659 \n    660     # This is a bit of a heuristic for nice results... we always rewrite\n~\\Anaconda3\\lib\\site-packages\\sympy\\series\\gruntz.py in limitinf(e, x)\n    426         e = e.subs(x, p)\n    427         x = p\n--> 428     c0, e0 = mrv_leadterm(e, x)\n    429     sig = sign(e0, x)\n    430     if sig == 1:\n~\\Anaconda3\\lib\\site-packages\\sympy\\series\\gruntz.py in mrv_leadterm(e, x)\n    511     w = Dummy(\"w\", real=True, positive=True, finite=True)\n    512     f, logw = rewrite(exps, Omega, x, w)\n--> 513     series = calculate_series(f, w, logx=logw)\n    514     return series.leadterm(w)\n    515 \n~\\Anaconda3\\lib\\site-packages\\sympy\\series\\gruntz.py in calculate_series(e, x, logx)\n    464     from sympy.polys import cancel\n    465 \n--> 466     for t in e.lseries(x, logx=logx):\n    467         t = cancel(t)\n    468 \n~\\Anaconda3\\lib\\site-packages\\sympy\\core\\expr.py in yield_lseries(s)\n   2635             def yield_lseries(s):\n   2636                 \"\"\"Return terms of lseries one at a time.\"\"\"\n-> 2637                 for si in s:\n   2638                     if not si.is_Add:\n   2639                         yield si\n~\\Anaconda3\\lib\\site-packages\\sympy\\core\\expr.py in _eval_lseries(self, x, logx)\n   2700         # terms.\n   2701         n = 0\n-> 2702         series = self._eval_nseries(x, n=n, logx=logx)\n   2703         if not series.is_Order:\n   2704             if series.is_Add:\n~\\Anaconda3\\lib\\site-packages\\sympy\\core\\function.py in _eval_nseries(self, x, n, logx)\n    685         cf = Order(arg.as_leading_term(x), x).getn()\n    686         if cf != 0:\n--> 687             nterms = int(nterms / cf)\n    688         for i in range(nterms):\n    689             g = self.taylor_term(i, arg, g)\nTypeError: unsupported operand type(s) for /: 'int' and 'NoneType'\n"}, {"link": "https://stackoverflow.com/questions/30190069/make-an-object-immutable", "error": ">>> a = ([1,2],[2,3])\n>>> type(a)\n<type 'tuple'>\n>>> d = dict()\n>>> d[a] = 1\nTraceback (most recent call last):\n  File \"<stdin>\", line 1, in <module>\nTypeError: unhashable type: 'list'\n"}, {"link": "https://stackoverflow.com/questions/11808367/django-nameerror-name-os-is-not-defined", "error": "Traceback (most recent call last):\n  File \"./manage.py\", line 11, in <module>\n    import settings\n  File \"/home/ubuntu/xx/settings.py\", line 140, in <module>\n    GOOGLE_OAUTH2_CLIENT_ID = os.environ['GOOGLE_OAUTH2_CLIENT_ID']\nNameError: name 'os' is not defined\n"}, {"link": "https://stackoverflow.com/questions/44651760/django-db-migrations-exceptions-inconsistentmigrationhistory", "error": "Traceback (most recent call last):\nFile \"manage.py\", line 22, in <module>\nexecute_from_command_line(sys.argv)\nFile \"/home/hari/project/env/local/lib/python2.7/site-     packages/django/core/management/__init__.py\", line 363, in execute_from_command_line\nutility.execute()\nFile \"/home/hari/project/env/local/lib/python2.7/site-packages/django/core/management/__init__.py\", line 355, in execute\nself.fetch_command(subcommand).run_from_argv(self.argv)\nFile \"/home/hari/project/env/local/lib/python2.7/site-packages/django/core/management/base.py\", line 283, in run_from_argv\nself.execute(*args, **cmd_options)\nFile \"/home/hari/project/env/local/lib/python2.7/site-packages/django/core/management/base.py\", line 330, in execute\noutput = self.handle(*args, **options)\nFile \"/home/hari/project/env/local/lib/python2.7/site-packages/django/core/management/commands/migrate.py\", line 86, in handle\nexecutor.loader.check_consistent_history(connection)\nFile \"/home/hari/project/env/local/lib/python2.7/site-packages/django/db/migrations/loader.py\", line 298, in check_consistent_history\nconnection.alias,\ndjango.db.migrations.exceptions.InconsistentMigrationHistory: Migration admin.0001_initial is applied before its dependency account.0001_initial on database 'default'.\n"}, {"link": "https://stackoverflow.com/questions/28557466/python-requests-exception-connectionerror-connection-aborted-badstatusline", "error": "Traceback (most recent call last):\nFile \"getAPids.py\", line 34, in <module>\nr=requests.get(userloginurl,params=payload)\n  File \"C:\\Users\\garvitab\\python\\lib\\site-packages\\requests\\api.py\", line 65, in\n get\nreturn request('get', url, **kwargs)\nFile \"C:\\Users\\garvitab\\python\\lib\\site-packages\\requests\\api.py\", line 49, in\nrequest\nresponse = session.request(method=method, url=url, **kwargs)\nFile \"C:\\Users\\garvitab\\python\\lib\\site-packages\\requests\\sessions.py\", line 4\n61, in request\nresp = self.send(prep, **send_kwargs)\nFile \"C:\\Users\\garvitab\\python\\lib\\site-packages\\requests\\sessions.py\", line 5\n73, in send\nr = adapter.send(request, **kwargs)\n File \"C:\\Users\\garvitab\\python\\lib\\site-packages\\requests\\adapters.py\", line 4\n15, in send\nraise ConnectionError(err, request=request)\nrequests.exceptions.ConnectionError: ('Connection aborted.', BadStatusLine(\"''\",\n))\n"}, {"link": "https://stackoverflow.com/questions/65449280/tensorflow-giving-unknow-dtype-policy", "error": "---------------------------------------------------------------------------\nValueError                                Traceback (most recent call last)\n<ipython-input-2-2ca8d6accabd> in <module>\n     10 policy = mixed_precision.Policy('mixed_bfloat16')\n     11 mixed_precision.set_policy(policy)\n---> 12 model = tf.keras.models.load_model(r\"../input/model-for-training/effieceintnettpurandomcrop.h5\")\n     13 \n     14 model.summary()\n\n/opt/conda/lib/python3.7/site-packages/tensorflow/python/keras/saving/save.py in load_model(filepath, custom_objects, compile)\n    182     if (h5py is not None and (\n    183         isinstance(filepath, h5py.File) or h5py.is_hdf5(filepath))):\n--> 184       return hdf5_format.load_model_from_hdf5(filepath, custom_objects, compile)\n    185 \n    186     if sys.version_info >= (3, 4) and isinstance(filepath, pathlib.Path):\n\n/opt/conda/lib/python3.7/site-packages/tensorflow/python/keras/saving/hdf5_format.py in load_model_from_hdf5(filepath, custom_objects, compile)\n    176     model_config = json.loads(model_config.decode('utf-8'))\n    177     model = model_config_lib.model_from_config(model_config,\n--> 178                                                custom_objects=custom_objects)\n    179 \n    180     # set weights\n\n/opt/conda/lib/python3.7/site-packages/tensorflow/python/keras/saving/model_config.py in model_from_config(config, custom_objects)\n     53                     '`Sequential.from_config(config)`?')\n     54   from tensorflow.python.keras.layers import deserialize  # pylint: disable=g-import-not-at-top\n---> 55   return deserialize(config, custom_objects=custom_objects)\n     56 \n     57 \n\n/opt/conda/lib/python3.7/site-packages/tensorflow/python/keras/layers/serialization.py in deserialize(config, custom_objects)\n    107       module_objects=globs,\n    108       custom_objects=custom_objects,\n--> 109       printable_module_name='layer')\n\n/opt/conda/lib/python3.7/site-packages/tensorflow/python/keras/utils/generic_utils.py in deserialize_keras_object(identifier, module_objects, custom_objects, printable_module_name)\n    371             custom_objects=dict(\n    372                 list(_GLOBAL_CUSTOM_OBJECTS.items()) +\n--> 373                 list(custom_objects.items())))\n    374       with CustomObjectScope(custom_objects):\n    375         return cls.from_config(cls_config)\n\n/opt/conda/lib/python3.7/site-packages/tensorflow/python/keras/engine/sequential.py in from_config(cls, config, custom_objects)\n    396     for layer_config in layer_configs:\n    397       layer = layer_module.deserialize(layer_config,\n--> 398                                        custom_objects=custom_objects)\n    399       model.add(layer)\n    400     if (not model.inputs and build_input_shape and\n\n/opt/conda/lib/python3.7/site-packages/tensorflow/python/keras/layers/serialization.py in deserialize(config, custom_objects)\n    107       module_objects=globs,\n    108       custom_objects=custom_objects,\n--> 109       printable_module_name='layer')\n\n/opt/conda/lib/python3.7/site-packages/tensorflow/python/keras/utils/generic_utils.py in deserialize_keras_object(identifier, module_objects, custom_objects, printable_module_name)\n    373                 list(custom_objects.items())))\n    374       with CustomObjectScope(custom_objects):\n--> 375         return cls.from_config(cls_config)\n    376     else:\n    377       # Then `cls` may be a function returning a class.\n\n/opt/conda/lib/python3.7/site-packages/tensorflow/python/keras/engine/base_layer.py in from_config(cls, config)\n    653         A layer instance.\n    654     \"\"\"\n--> 655     return cls(**config)\n    656 \n    657   def compute_output_shape(self, input_shape):\n\n/opt/conda/lib/python3.7/site-packages/tensorflow/python/keras/layers/normalization.py in __init__(self, axis, momentum, epsilon, center, scale, beta_initializer, gamma_initializer, moving_mean_initializer, moving_variance_initializer, beta_regularizer, gamma_regularizer, beta_constraint, gamma_constraint, renorm, renorm_clipping, renorm_momentum, fused, trainable, virtual_batch_size, adjustment, name, **kwargs)\n    198                **kwargs):\n    199     super(BatchNormalizationBase, self).__init__(\n--> 200         name=name, **kwargs)\n    201     if isinstance(axis, (list, tuple)):\n    202       self.axis = axis[:]\n\n/opt/conda/lib/python3.7/site-packages/tensorflow/python/training/tracking/base.py in _method_wrapper(self, *args, **kwargs)\n    454     self._self_setattr_tracking = False  # pylint: disable=protected-access\n    455     try:\n--> 456       result = method(self, *args, **kwargs)\n    457     finally:\n    458       self._self_setattr_tracking = previous_value  # pylint: disable=protected-access\n\n/opt/conda/lib/python3.7/site-packages/tensorflow/python/keras/engine/base_layer.py in __init__(self, trainable, name, dtype, dynamic, **kwargs)\n    336     # fields, like the loss scale, are used by Models. For subclassed networks,\n    337     # the compute and variable dtypes are used as like any ordinary layer.\n--> 338     self._set_dtype_policy(dtype)\n    339     # Boolean indicating whether the layer automatically casts its inputs to the\n    340     # layer's compute_dtype.\n\n/opt/conda/lib/python3.7/site-packages/tensorflow/python/keras/engine/base_layer.py in _set_dtype_policy(self, dtype)\n   1986       self._dtype_policy = dtype\n   1987     elif isinstance(dtype, dict):\n-> 1988       self._dtype_policy = policy.deserialize(dtype)\n   1989     elif dtype:\n   1990       self._dtype_policy = policy.Policy(dtypes.as_dtype(dtype).name)\n\n/opt/conda/lib/python3.7/site-packages/tensorflow/python/keras/mixed_precision/experimental/policy.py in deserialize(config, custom_objects)\n    628       module_objects=module_objects,\n    629       custom_objects=custom_objects,\n--> 630       printable_module_name='dtype policy')\n\n/opt/conda/lib/python3.7/site-packages/tensorflow/python/keras/utils/generic_utils.py in deserialize_keras_object(identifier, module_objects, custom_objects, printable_module_name)\n    360     config = identifier\n    361     (cls, cls_config) = class_and_config_for_serialized_keras_object(\n--> 362         config, module_objects, custom_objects, printable_module_name)\n    363 \n    364     if hasattr(cls, 'from_config'):\n\n/opt/conda/lib/python3.7/site-packages/tensorflow/python/keras/utils/generic_utils.py in class_and_config_for_serialized_keras_object(config, module_objects, custom_objects, printable_module_name)\n    319   cls = get_registered_object(class_name, custom_objects, module_objects)\n    320   if cls is None:\n--> 321     raise ValueError('Unknown ' + printable_module_name + ': ' + class_name)\n    322 \n    323   cls_config = config['config']\n\nValueError: Unknown dtype policy: PolicyV1\n\n"}, {"link": "https://stackoverflow.com/questions/67769189/how-do-i-fix-this-webbot-error-for-python", "error": "Traceback (most recent call last):\n  File \".../Python/ok.py\", line 1, in <module>\n    from webbot import Browser\n  File \".../Python/webbot.py\", line 2, in <module>\n    web = webbot.Browser()\nAttributeError: partially initialized module 'webbot' has no attribute 'Browser' (most likely due to a circular import)\n"}, {"link": "https://stackoverflow.com/questions/46913841/python-mysql-typeerror-must-be-str-not-tuple", "error": "Traceback (most recent call last):\n  File \"/home/luke/projects/vuln_backend/vuln_backend/download.py\", line 61, in download\n    'v3/archive/collection/?type=' + x)\nTypeError: must be str, not tuple\n"}, {"link": "https://stackoverflow.com/questions/67765852/i-cant-repeat-a-loop-because-int-or-float-object-is-not-callable", "error": "Quiere ingresar un profesor?: si\nIngrese nombre completo del docente: Emanuel Leal\nIngrese la cantidad de horas trabajadas por semana: 42\nIngresa el valor de la hora: 5000\nEl sueldo bruto del docente Emanuel Leal es: 1260000.0 mensuales\nLos descuentos de parafiscales, salud y pension son:  214200.0 mensuales\nEl sueldo neto del docente Emanuel Leal es 1045800.0: mensuales\nLas proviciones por prima, cesantias, interes de cesantias y vacaciones son: 275058.0\nQuiere ingresar un profesor?: si\nIngrese nombre completo del docente: Ana Julia\nIngrese la cantidad de horas trabajadas por semana: 37\nIngresa el valor de la hora: 5600\nTraceback (most recent call last):\nFile \"/home/master/Documentos/proyectos/misiontic/ciclo1/semana5/reto4/reto4.py\", line 43, in <module>\nsueldoBruto = sueldoBruto(horas, valorHoras)\nTypeError: 'float' object is not callable\n"}, {"link": "https://stackoverflow.com/questions/49787327/selenium-on-mac-message-chromedriver-executable-may-have-wrong-permissions", "error": "Traceback (most recent call last):\n  File \"/Users/godsinred/Desktop/InstagramLiker/GmailAccountGenerator.py\", line 10, in <module>\n    driver = webdriver.Chrome()\n  File \"/Library/Frameworks/Python.framework/Versions/3.6/lib/python3.6/site-packages/selenium/webdriver/chrome/webdriver.py\", line 68, in __init__\n    self.service.start()\n  File \"/Library/Frameworks/Python.framework/Versions/3.6/lib/python3.6/site-packages/selenium/webdriver/common/service.py\", line 88, in start\n    os.path.basename(self.path), self.start_error_message)\nselenium.common.exceptions.WebDriverException: Message: 'chromedriver' executable may have wrong permissions. Please see https://sites.google.com/a/chromium.org/chromedriver/home\n"}, {"link": "https://stackoverflow.com/questions/67710502/sublime-text-3-shows-eoferror-when-i-try-to-run-python-scripts-with-sublimerep", "error": "Traceback (most recent call last):\n  File \"C:\\Users\\Al\\AppData\\Roaming\\Sublime Text 3\\Packages\\SublimeREPL\\sublimerepl.py\", line 495, in open\n    rv = ReplView(view, r, syntax, repl_restart_args)\n  File \"C:\\Users\\Al\\AppData\\Roaming\\Sublime Text 3\\Packages\\SublimeREPL\\sublimerepl.py\", line 186, in __init__\n    self._history = PersistentHistory(self.external_id)\n  File \"C:\\Users\\Al\\AppData\\Roaming\\Sublime Text 3\\Packages\\SublimeREPL\\sublimerepl.py\", line 140, in __init__\n    self._db.create(\"external_id\", \"command\", \"ts\", mode=\"open\")\n  File \"C:\\Users\\Al\\AppData\\Roaming\\Sublime Text 3\\Packages\\SublimeREPL\\repllibs\\PyDbLite.py\", line 193, in create\n    return self.open()\n  File \"C:\\Users\\Al\\AppData\\Roaming\\Sublime Text 3\\Packages\\SublimeREPL\\repllibs\\PyDbLite.py\", line 246, in open\n    self.fields = pickle.load(_in)\nEOFError\nerror: EOFError()\n"}, {"link": "https://stackoverflow.com/questions/67763930/script-to-remove-lines-that-have-same-string-at-the-end-of-the-line-and-save-the", "error": "Traceback (most recent call last):\n  File \"E:\\CIT656\\pythonProjects\\CIT656_Spring21\\Assignment_03.py\", line 29, in <module>\n    edge_weight = float(line_items[2])\nValueError: could not convert string to float: 'edge_weight'\n\nProcess finished with exit code 1\n"}, {"link": "https://stackoverflow.com/questions/67763341/how-to-delete-row-of-table-in-sqlite3-using-django-shell", "error": "python manage.py migrate\nSystem check identified some issues:\n\nWARNINGS:\n?: (urls.W005) URL namespace 'flights' isn't unique. You may not be able to \nreverse all URLs in this namespace    \nOperations to perform:\n  Apply all migrations: admin, auth, contenttypes, flights, sessions        \nRunning migrations:\n  Applying flights.0002_auto_20210530_1202...Traceback (most recent call last):\n  File \"C:\\Users\\kaij\\Documents\\cs50\\airline\\manage.py\", line 22, in <module>\n    main()\n  File \"C:\\Users\\kaij\\Documents\\cs50\\airline\\manage.py\", line 18, in main   \n    execute_from_command_line(sys.argv)\n  File \"C:\\Users\\kaij\\AppData\\Local\\Programs\\Python\\Python39\\lib\\site-packages\\django\\core\\management\\__init__.py\", line 419, in execute_from_command_line\n    utility.execute()\n  File \"C:\\Users\\kaij\\AppData\\Local\\Programs\\Python\\Python39\\lib\\site-packages\\django\\core\\management\\__init__.py\", line 413, in execute\n    self.fetch_command(subcommand).run_from_argv(self.argv)\n  File \"C:\\Users\\kaij\\AppData\\Local\\Programs\\Python\\Python39\\lib\\site-packages\\django\\core\\management\\base.py\", line 354, in run_from_argv\n    self.execute(*args, **cmd_options)  File \"C:\\Users\\kaij\\AppData\\Local\\Programs\\Python\\Python39\\lib\\site-packages\\django\\core\\management\\base.py\", line 398, in execute\n    output = self.handle(*args, **options)\n  File \"C:\\Users\\kaij\\AppData\\Local\\Programs\\Python\\Python39\\lib\\site-packages\\django\\core\\management\\base.py\", line 89, in wrapped\n    res = handle_func(*args, **kwargs)  File \"C:\\Users\\kaij\\AppData\\Local\\Programs\\Python\\Python39\\lib\\site-packages\\django\\core\\management\\commands\\migrate.py\", line 244, in handle\n    post_migrate_state = executor.migrate(\n  File \"C:\\Users\\kaij\\AppData\\Local\\Programs\\Python\\Python39\\lib\\site-packages\\django\\db\\migrations\\executor.py\", \nline 117, in migrate\n    state = self._migrate_all_forwards(state, plan, full_plan, fake=fake, fake_initial=fake_initial)\n  File \"C:\\Users\\kaij\\AppData\\Local\\Programs\\Python\\Python39\\lib\\site-packages\\django\\db\\migrations\\executor.py\", \nline 147, in _migrate_all_forwards    \n    state = self.apply_migration(state, migration, fake=fake, fake_initial=fake_initial)\n  File \"C:\\Users\\kaij\\AppData\\Local\\Programs\\Python\\Python39\\lib\\site-packages\\django\\db\\migrations\\executor.py\", \nline 230, in apply_migration\n    migration_recorded = True\n  File \"C:\\Users\\kaij\\AppData\\Local\\Programs\\Python\\Python39\\lib\\site-packages\\django\\db\\backends\\sqlite3\\schema.py\", line 35, in __exit__\n    self.connection.check_constraints()\n  File \"C:\\Users\\kaij\\AppData\\Local\\Programs\\Python\\Python39\\lib\\site-packages\\django\\db\\backends\\sqlite3\\base.py\", line 353, in check_constraints, line 353, in check_constraints      \n    raise IntegrityError(             w in table 'flights_flight' with primary key '1' has an invalid foreign k\ndjango.db.utils.IntegrityError: The rots_flight.origin_id contains a value 'New Yoesponding value in flights_aiw in table 'flights_flight' with prima value in flights_airport.id.ry key '1' has an invalid foreign key:e> flights_flight.origin_id contains a value 'New York' that does not have a corresponding value in flights_airport.id.\nPS C:\\Users\\kaij\\Documents\\cs50\\airline>\n"}, {"link": "https://stackoverflow.com/questions/67758195/discord-py-how-to-assign-someone-a-role", "error": "Ignoring exception in command mute:\nTraceback (most recent call last):\n  File \"C:\\Users\\gathi\\AppData\\Local\\Programs\\Python\\Python39\\lib\\site-packages\\discord\\ext\\commands\\core.py\", line 85, in wrapped\n    ret = await coro(*args, **kwargs)\n  File \"C:\\Users\\gathi\\Vscode\\Discord_Bot\\tutorial.py\", line 61, in mute\n    await member.edit(roles=[role]) # 848410518154117130\n  File \"C:\\Users\\gathi\\AppData\\Local\\Programs\\Python\\Python39\\lib\\site-packages\\discord\\member.py\", line 681, in edit\n    await http.edit_member(guild_id, self.id, reason=reason, **payload)\n  File \"C:\\Users\\gathi\\AppData\\Local\\Programs\\Python\\Python39\\lib\\site-packages\\discord\\http.py\", line 248, in request\n    raise Forbidden(r, data)\ndiscord.errors.Forbidden: 403 Forbidden (error code: 50013): Missing Permissions\n\nThe above exception was the direct cause of the following exception:\n\nTraceback (most recent call last):\n  File \"C:\\Users\\gathi\\AppData\\Local\\Programs\\Python\\Python39\\lib\\site-packages\\discord\\ext\\commands\\bot.py\", line 939, in invoke\n    await ctx.command.invoke(ctx)\n  File \"C:\\Users\\gathi\\AppData\\Local\\Programs\\Python\\Python39\\lib\\site-packages\\discord\\ext\\commands\\core.py\", line 863, in invoke\n    await injected(*ctx.args, **ctx.kwargs)\n  File \"C:\\Users\\gathi\\AppData\\Local\\Programs\\Python\\Python39\\lib\\site-packages\\discord\\ext\\commands\\core.py\", line 94, in wrapped\n    raise CommandInvokeError(exc) from exc\ndiscord.ext.commands.errors.CommandInvokeError: Command raised an exception: Forbidden: 403 Forbidden (error code: 50013): Missing Permissions\n"}, {"link": "https://stackoverflow.com/questions/37589254/not-able-to-get-item-from-aws-dynamodb-using-python", "error": "Traceback (most recent call last):\n File \"get-data-dynamodb-boto3.py\", line 19, in <module>\n    response = table.get_item(TableName='Garbage_collector_table', Key={'topic': my_topic})   File\n \"/usr/local/lib/python2.7/dist-packages/boto3/resources/factory.py\",\n line 518, in do_action\n     response = action(self, *args, **kwargs)   File \"/usr/local/lib/python2.7/dist-packages/boto3/resources/action.py\",\n line 83, in __call__\n     response = getattr(parent.meta.client, operation_name)(**params)   File \"/usr/local/lib/python2.7/dist-packages/botocore/client.py\", line\n 258, in _api_call\n     return self._make_api_call(operation_name, kwargs)   File /usr/local/lib/python2.7/dist-packages/botocore/client.py\", line 548,\n in _make_api_call\n     raise ClientError(parsed_response, operation_name)\n"}, {"link": "https://stackoverflow.com/questions/38524332/declaring-decorator-inside-a-class", "error": "Traceback (most recent call last):\n  File \"C:\\Users\\cccvag\\workspace\\Test\\src\\module2.py\", line 2, in <module>\n    class TestWrapper():\n  File \"C:\\Users\\cccvag\\workspace\\Test\\src\\module2.py\", line 18, in     TestWrapper\n    @enter_exit_info\nTypeError: enter_exit_info() takes exactly 2 arguments (1 given)\n"}, {"link": "https://stackoverflow.com/questions/67760175/i-dont-know-why-this-python-code-for-replacing-all-occurences-of-a-substring-no", "error": "Traceback (most recent call last):\n  File \"f:/----/-----/---------/Fn_replace.py\", line 19, in <module>\n    replace_string(str,x,y)\n  File \"f:/----/-----/--------/Fn_replace.py\", line 5, in replace_string\n    if str[i] == x[0]:\nIndexError: string index out of range\n"}, {"link": "https://stackoverflow.com/questions/48577781/assertionerror-404-200-in-django-test", "error": "FAIL: test_abaout_page_status_code (pages.tests.SimpleTests)\n----------------------------------------------------------------------\nTraceback (most recent call last):\n  File \"C:\\Users\\User\\Dj\\simple\\pages\\tests.py\", line 10, in test_abaout_page_status_code\n    self.assertEquals(response.status_code, 200)\nAssertionError: 404 != 200\n"}, {"link": "https://stackoverflow.com/questions/51557902/beautifulsoup4-indexerror-list-index-out-of-range", "error": "Traceback (most recent call last):\n  File \"/home/ubuntu/workspace/Untitled1.py\", line 17, in <module>\n    for tr in soup.find_all('tr')[3]:\nIndexError: list index out of range\n"}, {"link": "https://stackoverflow.com/questions/53888909/modulenotfounderror-when-python-runs-as-a-job-in-sql-server-agent", "error": "Executed as user: DOMAIN\\SQLUser. Traceback (most recent call last): File \"PathToScript\\script.py\". line 1, in <module> import pyodbc ModuleNotFoundError: No module named 'pyodbc'. \n"}, {"link": "https://stackoverflow.com/questions/57230859/why-does-the-pycharm-show-attributeerror-module-numbers-has-no-attribute-num", "error": "Traceback (most recent call last):\n  File \"E:\\Program Files\\JetBrains\\PyCharm 2019.1\\helpers\\pydev\\pydevd.py\", line 15, in <module>\n    from _pydevd_bundle.pydevd_constants import IS_JYTH_LESS25, IS_PY34_OR_GREATER, IS_PY36_OR_GREATER, IS_PYCHARM, get_thread_id, \\\n  File \"E:\\Program Files\\JetBrains\\PyCharm 2019.1\\helpers\\pydev\\_pydevd_bundle\\pydevd_constants.py\", line 169, in <module>\n    from _pydev_imps._pydev_saved_modules import thread\n  File \"E:\\Program Files\\JetBrains\\PyCharm 2019.1\\helpers\\pydev\\_pydev_imps\\_pydev_saved_modules.py\", line 21, in <module>\n    import xmlrpc.client as xmlrpclib\n  File \"C:\\Users\\A\\AppData\\Local\\Programs\\Python\\Python37\\lib\\xmlrpc\\client.py\", line 135, in <module>\n    from decimal import Decimal\n  File \"C:\\Users\\A\\AppData\\Local\\Programs\\Python\\Python37\\lib\\decimal.py\", line 3, in <module>\n    from _decimal import *\nAttributeError: module 'numbers' has no attribute 'Number'\n"}]