[{"body": "<p>Here I have data to import from a CSV file.I wrote an equation inside the class and to solve the equation data will import from the CSV file. \nWhen I run my code I got an error like \"tuple indices must be integers or slices, not str\" using panda python.\nCan anyone help me to solve this problem?\nI upload my code and CSV file here.</p>\n\n<pre><code>def time_convert(x):\n    h,m,s = map(int,x.split(':'))\n    return (h*60+m)\n\ndef ph_convert(time,we,h,a,w):\n    while time &lt;= 30:\n        level = 1.1\n        level = float(level)\n        if w == 1:\n            ph= ((((6*we)+(1*h))/level -(4*a)))/time\n        else:\n            ph= ((6+((1*we)+(3*h))/level -(6 *a)))/time  \n        break\n    while time &lt;=60:\n        level = 1.25\n        level = float(level)\n        if w == 1:\n            ph= ((((6*we)+(1*h))/level -(4*a)))/time\n        else:\n            ph= ((6+((1*we)+(3*h))/level -(6 *a)))/time  \n        break\n    print(ph)\n\ndata = pd.read_csv('data1.csv')\ndata['time'] = data['time'].apply(time_convert)\nwe = data['we'].astype(float)\nh = data['h'].astype(float)\na = data['a'].astype(float)\nw = data['w'].astype(float)\ntime = data['time'].astype(float)\nprint(ph_convert(time,we,h,a,w))\n</code></pre>\n\n<p>Subset of my CSV file:</p>\n\n<pre><code>we      h   a   w   time\n48.1    150 53  1   6:15:00\n48.1    150 53  1   9:00:00\n48.1    150 53  1   9:25:00\n48.1    150 53  1   9:30:00\n48.1    150 53  1   11:00:00\n</code></pre>\n\n<p>Error:</p>\n\n<pre><code>ValueError                                Traceback (most recent call last)\n&lt;ipython-input-922-9fe360350b03&gt; in &lt;module&gt;()\n----&gt; 1 print(ph_convert(time,we,h,a,w))\n\n&lt;ipython-input-904-73455dabb050&gt; in ph_convert(time, we, h, a, w)\n      3    \n----&gt; 5         while time &lt;= 30:\n      6             level = 1.1\n      7             level = float(level)\n\n~\\Anaconda3\\lib\\site-packages\\pandas\\core\\generic.py in __nonzero__(self)\n   1571         raise ValueError(\"The truth value of a {0} is ambiguous. \"\n   1572                          \"Use a.empty, a.bool(), a.item(), a.any() or a.all().\"\n-&gt; 1573                          .format(self.__class__.__name__))\n   1574 \n   1575     __bool__ = __nonzero__\n\nValueError: The truth value of a Series is ambiguous. Use a.empty, a.bool(), a.item(), a.any() or a.all().\n</code></pre>\n", "link": "https://stackoverflow.com/questions/53588155/the-truth-value-of-a-series-is-ambiguous-use-a-empty-a-bool-a-item-a-any", "last_activity_date": 1622460093, "question_id": 53588155}, {"body": "<p>i try to install snap7 (to read from a S7-1200) with it's python-snap7 0.4 wrapper but i get always a traceback with the following simple code.</p>\n\n<pre><code>from time import sleep\nimport snap7\nfrom snap7.util import *\nimport struct\n\nplc = snap7.client.Client()\n</code></pre>\n\n<p>Traceback:</p>\n\n<pre><code> &gt;&gt;&gt; \nTraceback (most recent call last):\n  File \"Y:\\Lonnox\\Projekte\\Bibliothek\\Python und SPS\\S7-1200 Test.py\", line 6, in &lt;module&gt;\n    plc = snap7.client.Client()\n  File \"C:\\Python34\\lib\\site-packages\\snap7\\client.py\", line 30, in __init__\n    self.library = load_library()\n  File \"C:\\Python34\\lib\\site-packages\\snap7\\common.py\", line 54, in load_library\n    return Snap7Library(lib_location).cdll\n  File \"C:\\Python34\\lib\\site-packages\\snap7\\common.py\", line 46, in __init__\n    raise Snap7Exception(msg)\nsnap7.snap7exceptions.Snap7Exception: can't find snap7 library. If installed, try running ldconfig\n</code></pre>\n\n<p>The steps i do to install snap7 and python wrapper are:</p>\n\n<ol>\n<li>Download snap7 from sourceforge and copy snap7.dll and snap7.lib to system32 folder of windows 8 </li>\n<li>Install wrapper by using pip install python-snap7</li>\n</ol>\n\n<p>How to install snap7 on windows correctly ? </p>\n\n<p>[log of pip install][1]</p>\n", "link": "https://stackoverflow.com/questions/33697263/python-snap7-windows-cant-find-snap7-library", "last_activity_date": 1622459684, "question_id": 33697263}, {"body": "<p>I'm trying to restore a pickled config file from RLLib (<a href=\"https://stackoverflow.com/questions/62908522/error-callbacks-must-be-a-callable-method-that-returns-a-subclass-of-defaultc\">json didn't work as shown in this post</a>), and getting the following error:</p>\n<pre><code>config = pickle.load(open(f&quot;{path}/params.pkl&quot;, &quot;rb&quot;))\n\n---------------------------------------------------------------------------\nValueError                                Traceback (most recent call last)\n&lt;ipython-input-28-c964561b863c&gt; in &lt;module&gt;\n----&gt; 1 config = pickle.load(open(f&quot;{path}/params.pkl&quot;, &quot;rb&quot;))\n\nValueError: unsupported pickle protocol: 5\n\n</code></pre>\n<p>Python Version = 3.7.0</p>\n<p>How can I open this file in 3.7?</p>\n", "link": "https://stackoverflow.com/questions/63329657/python-3-7-error-unsupported-pickle-protocol-5", "last_activity_date": 1622455790, "question_id": 63329657}, {"body": "<p>In python I have a folder with three files</p>\n<pre><code>- __init__.py\n- module.py\n- test_module.py\n</code></pre>\n<p>in which the module <code>module.py</code> is imported inside the file <code>test_module.py</code> as follows:</p>\n<pre><code>from . import module\n</code></pre>\n<p>Of course, when I just run <code>test_module.py</code> I get an error</p>\n<pre class=\"lang-none prettyprint-override\"><code>&gt; python test_module.py\nTraceback (most recent call last):\n  File &quot;test_module.py&quot;, line 4, in &lt;module&gt;\n    from . import module\nImportError: attempted relative import with no known parent package\n</code></pre>\n<p>But as I set the <code>PYTHONPATH</code> to the absolute path to where I am working in</p>\n<pre><code>export PYTHONPATH=`pwd`\n</code></pre>\n<p>I expect the import to work (as I did set the <code>PYTHONPATH</code>). But to my surprise I get the same error!</p>\n<p>So can I fix the relative import error <strong>without any code change</strong>?</p>\n", "link": "https://stackoverflow.com/questions/67771207/how-to-fix-relative-import-error-in-python-without-code-change", "last_activity_date": 1622454091, "question_id": 67771207}, {"body": "<p>Using Python 3.x. When running the test case for the following code, I get the error - <code>NameError: name 'upper' is not defined</code>. I am attaching the file to test, the <code>File_P_third</code> file where is the code, and the unit test file <code>test_upper</code>.</p>\n<p>File <code>File_P_third</code>:</p>\n<pre><code>def upper_text(text):\n    return text.upper()\n</code></pre>\n<p>File <code>test_upper</code>:</p>\n<pre><code>import unittest\nimport File_P_third\n\n\nclass TestUpper(unittest.TestCase):\n    &quot;&quot;&quot;docstring for ClassName&quot;&quot;&quot;\n    def test_one_word(self):\n        text = 'hello!'\n        result = upper.upper_text(text)\n        self.assertEqual(result, 'HELLO!')\n        \n\nif __name__ == '__main__':\n    unittest.main()\n</code></pre>\n<p>My cmd`s exit text:</p>\n<pre><code>D:\\\u0414\u043e\u0445\u0443\u044f \u043f\u0440\u043e\u0433\u0440\u0430\u043c\u043c\u0438\u0441\u0442\\Projects&gt;python test_upper.py\nE\n======================================================================\nERROR: test_one_word (__main__.TestUpper)\n----------------------------------------------------------------------\nTraceback (most recent call last):\n  File &quot;test_upper.py&quot;, line 9, in test_one_word\n    result = upper.upper_text(text)\nNameError: name 'upper' is not defined\n\n----------------------------------------------------------------------\nRan 1 test in 0.001s\n\nFAILED (errors=1)\n</code></pre>\n<p>All files is in one directory and I still cant understand why is doesnt work. Can`t search the same problem in internet((</p>\n", "link": "https://stackoverflow.com/questions/66199655/python-unit-test-nameerror-name-upper-is-not-defined", "last_activity_date": 1622453936, "question_id": 66199655}, {"body": "<p>I'm studying sympy library for python for my study purpose. I'd like to calculate the next limit: \n<br><img src=\"https://latex.codecogs.com/gif.latex?%5Clim_%7Bx%5Cto&space;2-%7D&space;sgn&space;%5Ccos&space;%5Cfrac%7B%5Cpi%7D%7Bx%7D\" title=\"\\lim_{x\\to 2-} sgn \\cos \\frac{\\pi}{x}\" />\n<br>Thus, i have code:</p>\n\n<pre><code>import sympy as sp\nx = sp.Symbol('x')\nf = sp.sign(sp.cos(sp.pi/x))\nsp.limit(f, x, 2, '-')\n</code></pre>\n\n<p>But I'm getting next error:</p>\n\n<pre><code>TypeError                                 Traceback (most recent call last)\n&lt;ipython-input-31-56b1fd6b589d&gt; in &lt;module&gt;()\n      1 x = sp.Symbol('x')\n      2 f = sp.sign(sp.cos(sp.pi/x))\n----&gt; 3 sp.limit(f, x, 2, '-')\n~\\Anaconda3\\lib\\site-packages\\sympy\\series\\limits.py in limit(e, z, z0, dir)\n     47     \"\"\"\n     48 \n---&gt; 49     return Limit(e, z, z0, dir).doit(deep=False)\n     50 \n     51 \n~\\Anaconda3\\lib\\site-packages\\sympy\\series\\limits.py in doit(self, **hints)\n    178 \n    179         try:\n--&gt; 180             r = gruntz(e, z, z0, dir)\n    181             if r is S.NaN:\n    182                 raise PoleError()\n~\\Anaconda3\\lib\\site-packages\\sympy\\series\\gruntz.py in gruntz(e, z, z0, dir)\n    656         else:\n    657             raise NotImplementedError(\"dir must be '+' or '-'\")\n--&gt; 658         r = limitinf(e0, z)\n    659 \n    660     # This is a bit of a heuristic for nice results... we always rewrite\n~\\Anaconda3\\lib\\site-packages\\sympy\\series\\gruntz.py in limitinf(e, x)\n    426         e = e.subs(x, p)\n    427         x = p\n--&gt; 428     c0, e0 = mrv_leadterm(e, x)\n    429     sig = sign(e0, x)\n    430     if sig == 1:\n~\\Anaconda3\\lib\\site-packages\\sympy\\series\\gruntz.py in mrv_leadterm(e, x)\n    511     w = Dummy(\"w\", real=True, positive=True, finite=True)\n    512     f, logw = rewrite(exps, Omega, x, w)\n--&gt; 513     series = calculate_series(f, w, logx=logw)\n    514     return series.leadterm(w)\n    515 \n~\\Anaconda3\\lib\\site-packages\\sympy\\series\\gruntz.py in calculate_series(e, x, logx)\n    464     from sympy.polys import cancel\n    465 \n--&gt; 466     for t in e.lseries(x, logx=logx):\n    467         t = cancel(t)\n    468 \n~\\Anaconda3\\lib\\site-packages\\sympy\\core\\expr.py in yield_lseries(s)\n   2635             def yield_lseries(s):\n   2636                 \"\"\"Return terms of lseries one at a time.\"\"\"\n-&gt; 2637                 for si in s:\n   2638                     if not si.is_Add:\n   2639                         yield si\n~\\Anaconda3\\lib\\site-packages\\sympy\\core\\expr.py in _eval_lseries(self, x, logx)\n   2700         # terms.\n   2701         n = 0\n-&gt; 2702         series = self._eval_nseries(x, n=n, logx=logx)\n   2703         if not series.is_Order:\n   2704             if series.is_Add:\n~\\Anaconda3\\lib\\site-packages\\sympy\\core\\function.py in _eval_nseries(self, x, n, logx)\n    685         cf = Order(arg.as_leading_term(x), x).getn()\n    686         if cf != 0:\n--&gt; 687             nterms = int(nterms / cf)\n    688         for i in range(nterms):\n    689             g = self.taylor_term(i, arg, g)\nTypeError: unsupported operand type(s) for /: 'int' and 'NoneType'\n</code></pre>\n\n<p>What's the problem? I was easily calculating limits and haven't such error before. Is there a way to fix it? I haven't found one.</p>\n", "link": "https://stackoverflow.com/questions/53175387/sympy-left-sided-limit-of-sign-function", "last_activity_date": 1622452437, "question_id": 53175387}, {"body": "<p>I have a <code>defaultdict(list)</code> which I'd like to make immutable so that I can add objects of this type to a set. I have an idea as to how I can make it immutable, but it would require me write a few lines of code. Is there not a simpler way of doing this in python?</p>\n\n<p>Isn't it common in python to populate, for example a <code>defaultdict(list)</code>, while parsing a piece of data before freezing it once the parsing is complete?</p>\n\n<p>Its also the case that an object can be of type tuple but can't be used as a dict key, for example:</p>\n\n<pre><code>&gt;&gt;&gt; a = ([1,2],[2,3])\n&gt;&gt;&gt; type(a)\n&lt;type 'tuple'&gt;\n&gt;&gt;&gt; d = dict()\n&gt;&gt;&gt; d[a] = 1\nTraceback (most recent call last):\n  File \"&lt;stdin&gt;\", line 1, in &lt;module&gt;\nTypeError: unhashable type: 'list'\n</code></pre>\n\n<p>Why there exists a tuple of lists in python is also something I dont understand.</p>\n", "link": "https://stackoverflow.com/questions/30190069/make-an-object-immutable", "last_activity_date": 1622452355, "question_id": 30190069}, {"body": "<p>When I try to follow <a href=\"http://ghickman.co.uk/2012/07/22/google-oauth2-sso-with-django.html\" rel=\"nofollow noreferrer\">this tutorial</a> to install Google-auth2 on my Django 1.4 I get this error:</p>\n<pre><code>Traceback (most recent call last):\n  File &quot;./manage.py&quot;, line 11, in &lt;module&gt;\n    import settings\n  File &quot;/home/ubuntu/xx/settings.py&quot;, line 140, in &lt;module&gt;\n    GOOGLE_OAUTH2_CLIENT_ID = os.environ['GOOGLE_OAUTH2_CLIENT_ID']\nNameError: name 'os' is not defined\n</code></pre>\n<p>This line is:</p>\n<pre><code>139- LOGIN_REDIRECT_URL = '/'\n\n**140- GOOGLE_OAUTH2_CLIENT_ID = os.environ['GOOGLE_OAUTH2_CLIENT_ID']**\n\n141- GOOGLE_OAUTH2_CLIENT_SECRET = os.environ['GOOGLE_OAUTH2_CLIENT_SECRET']\n142- GOOGLE_WHITE_LISTED_DOMAINS = ['mydomain.org']\nSOCIAL_AUTH_USER_MODEL = 'auth.User'\n</code></pre>\n", "link": "https://stackoverflow.com/questions/11808367/django-nameerror-name-os-is-not-defined", "last_activity_date": 1622449884, "question_id": 11808367}, {"body": "<p>When I run <code>python manage.py migrate</code> on my Django project, I get the following error:</p>\n\n<pre><code>Traceback (most recent call last):\nFile \"manage.py\", line 22, in &lt;module&gt;\nexecute_from_command_line(sys.argv)\nFile \"/home/hari/project/env/local/lib/python2.7/site-     packages/django/core/management/__init__.py\", line 363, in execute_from_command_line\nutility.execute()\nFile \"/home/hari/project/env/local/lib/python2.7/site-packages/django/core/management/__init__.py\", line 355, in execute\nself.fetch_command(subcommand).run_from_argv(self.argv)\nFile \"/home/hari/project/env/local/lib/python2.7/site-packages/django/core/management/base.py\", line 283, in run_from_argv\nself.execute(*args, **cmd_options)\nFile \"/home/hari/project/env/local/lib/python2.7/site-packages/django/core/management/base.py\", line 330, in execute\noutput = self.handle(*args, **options)\nFile \"/home/hari/project/env/local/lib/python2.7/site-packages/django/core/management/commands/migrate.py\", line 86, in handle\nexecutor.loader.check_consistent_history(connection)\nFile \"/home/hari/project/env/local/lib/python2.7/site-packages/django/db/migrations/loader.py\", line 298, in check_consistent_history\nconnection.alias,\ndjango.db.migrations.exceptions.InconsistentMigrationHistory: Migration admin.0001_initial is applied before its dependency account.0001_initial on database 'default'.\n</code></pre>\n\n<p>I have a user model like below:</p>\n\n<pre><code>class User(AbstractUser):\n    place = models.CharField(max_length=64, null=True, blank=True)\n    address = models.CharField(max_length=128, null=True, blank=True)\n</code></pre>\n\n<p>How can I solve this problem?</p>\n", "link": "https://stackoverflow.com/questions/44651760/django-db-migrations-exceptions-inconsistentmigrationhistory", "last_activity_date": 1622449572, "question_id": 44651760}, {"body": "<p>I am trying to use the Python requests module to issue Http GET commands to access some REST based APIs. The urls are working fine on a RESTClient but when I use the same url in python, I get a connection error.</p>\n\n<p>The code I am trying to execute is:</p>\n\n<pre><code>payload={\"mac\":new_mac,\"token\":token}\nuserloginurl=\"http://192.168.1.40:9119/uid\"\nr=requests.get(userloginurl,params=payload)\nprint(r.url)\n</code></pre>\n\n<p>If I test this url using RESTClient, I get a 200 OK status code in the response header along with some more fields.\n<img src=\"https://i.stack.imgur.com/RNyvl.png\" alt=\"enter image description here\">\n But this is not working with python requests. The traceback of the error is shown below:</p>\n\n<pre><code>Traceback (most recent call last):\nFile \"getAPids.py\", line 34, in &lt;module&gt;\nr=requests.get(userloginurl,params=payload)\n  File \"C:\\Users\\garvitab\\python\\lib\\site-packages\\requests\\api.py\", line 65, in\n get\nreturn request('get', url, **kwargs)\nFile \"C:\\Users\\garvitab\\python\\lib\\site-packages\\requests\\api.py\", line 49, in\nrequest\nresponse = session.request(method=method, url=url, **kwargs)\nFile \"C:\\Users\\garvitab\\python\\lib\\site-packages\\requests\\sessions.py\", line 4\n61, in request\nresp = self.send(prep, **send_kwargs)\nFile \"C:\\Users\\garvitab\\python\\lib\\site-packages\\requests\\sessions.py\", line 5\n73, in send\nr = adapter.send(request, **kwargs)\n File \"C:\\Users\\garvitab\\python\\lib\\site-packages\\requests\\adapters.py\", line 4\n15, in send\nraise ConnectionError(err, request=request)\nrequests.exceptions.ConnectionError: ('Connection aborted.', BadStatusLine(\"''\",\n))\n</code></pre>\n\n<p>I looked up for the cause of the problem. Possibly, the response received is not formatted correctly. Is there a way to handle this problem?</p>\n\n<p>Thanks in advance.</p>\n", "link": "https://stackoverflow.com/questions/28557466/python-requests-exception-connectionerror-connection-aborted-badstatusline", "last_activity_date": 1622449524, "question_id": 28557466}, {"body": "<p>I Am trying to train a model  in Colab and then transferring it to Kaggle. The Model seems to Work fine in Colab as a .h5 model. The problem seems to be with Efficient net B4 and after in Kaggle. There is No Documentation about This. I am training this model on a TPU and doing the inference on a GPU but even if i train the model on GPU this problem is There.</p>\n<p>My error Log</p>\n<pre><code>---------------------------------------------------------------------------\nValueError                                Traceback (most recent call last)\n&lt;ipython-input-2-2ca8d6accabd&gt; in &lt;module&gt;\n     10 policy = mixed_precision.Policy('mixed_bfloat16')\n     11 mixed_precision.set_policy(policy)\n---&gt; 12 model = tf.keras.models.load_model(r&quot;../input/model-for-training/effieceintnettpurandomcrop.h5&quot;)\n     13 \n     14 model.summary()\n\n/opt/conda/lib/python3.7/site-packages/tensorflow/python/keras/saving/save.py in load_model(filepath, custom_objects, compile)\n    182     if (h5py is not None and (\n    183         isinstance(filepath, h5py.File) or h5py.is_hdf5(filepath))):\n--&gt; 184       return hdf5_format.load_model_from_hdf5(filepath, custom_objects, compile)\n    185 \n    186     if sys.version_info &gt;= (3, 4) and isinstance(filepath, pathlib.Path):\n\n/opt/conda/lib/python3.7/site-packages/tensorflow/python/keras/saving/hdf5_format.py in load_model_from_hdf5(filepath, custom_objects, compile)\n    176     model_config = json.loads(model_config.decode('utf-8'))\n    177     model = model_config_lib.model_from_config(model_config,\n--&gt; 178                                                custom_objects=custom_objects)\n    179 \n    180     # set weights\n\n/opt/conda/lib/python3.7/site-packages/tensorflow/python/keras/saving/model_config.py in model_from_config(config, custom_objects)\n     53                     '`Sequential.from_config(config)`?')\n     54   from tensorflow.python.keras.layers import deserialize  # pylint: disable=g-import-not-at-top\n---&gt; 55   return deserialize(config, custom_objects=custom_objects)\n     56 \n     57 \n\n/opt/conda/lib/python3.7/site-packages/tensorflow/python/keras/layers/serialization.py in deserialize(config, custom_objects)\n    107       module_objects=globs,\n    108       custom_objects=custom_objects,\n--&gt; 109       printable_module_name='layer')\n\n/opt/conda/lib/python3.7/site-packages/tensorflow/python/keras/utils/generic_utils.py in deserialize_keras_object(identifier, module_objects, custom_objects, printable_module_name)\n    371             custom_objects=dict(\n    372                 list(_GLOBAL_CUSTOM_OBJECTS.items()) +\n--&gt; 373                 list(custom_objects.items())))\n    374       with CustomObjectScope(custom_objects):\n    375         return cls.from_config(cls_config)\n\n/opt/conda/lib/python3.7/site-packages/tensorflow/python/keras/engine/sequential.py in from_config(cls, config, custom_objects)\n    396     for layer_config in layer_configs:\n    397       layer = layer_module.deserialize(layer_config,\n--&gt; 398                                        custom_objects=custom_objects)\n    399       model.add(layer)\n    400     if (not model.inputs and build_input_shape and\n\n/opt/conda/lib/python3.7/site-packages/tensorflow/python/keras/layers/serialization.py in deserialize(config, custom_objects)\n    107       module_objects=globs,\n    108       custom_objects=custom_objects,\n--&gt; 109       printable_module_name='layer')\n\n/opt/conda/lib/python3.7/site-packages/tensorflow/python/keras/utils/generic_utils.py in deserialize_keras_object(identifier, module_objects, custom_objects, printable_module_name)\n    373                 list(custom_objects.items())))\n    374       with CustomObjectScope(custom_objects):\n--&gt; 375         return cls.from_config(cls_config)\n    376     else:\n    377       # Then `cls` may be a function returning a class.\n\n/opt/conda/lib/python3.7/site-packages/tensorflow/python/keras/engine/base_layer.py in from_config(cls, config)\n    653         A layer instance.\n    654     &quot;&quot;&quot;\n--&gt; 655     return cls(**config)\n    656 \n    657   def compute_output_shape(self, input_shape):\n\n/opt/conda/lib/python3.7/site-packages/tensorflow/python/keras/layers/normalization.py in __init__(self, axis, momentum, epsilon, center, scale, beta_initializer, gamma_initializer, moving_mean_initializer, moving_variance_initializer, beta_regularizer, gamma_regularizer, beta_constraint, gamma_constraint, renorm, renorm_clipping, renorm_momentum, fused, trainable, virtual_batch_size, adjustment, name, **kwargs)\n    198                **kwargs):\n    199     super(BatchNormalizationBase, self).__init__(\n--&gt; 200         name=name, **kwargs)\n    201     if isinstance(axis, (list, tuple)):\n    202       self.axis = axis[:]\n\n/opt/conda/lib/python3.7/site-packages/tensorflow/python/training/tracking/base.py in _method_wrapper(self, *args, **kwargs)\n    454     self._self_setattr_tracking = False  # pylint: disable=protected-access\n    455     try:\n--&gt; 456       result = method(self, *args, **kwargs)\n    457     finally:\n    458       self._self_setattr_tracking = previous_value  # pylint: disable=protected-access\n\n/opt/conda/lib/python3.7/site-packages/tensorflow/python/keras/engine/base_layer.py in __init__(self, trainable, name, dtype, dynamic, **kwargs)\n    336     # fields, like the loss scale, are used by Models. For subclassed networks,\n    337     # the compute and variable dtypes are used as like any ordinary layer.\n--&gt; 338     self._set_dtype_policy(dtype)\n    339     # Boolean indicating whether the layer automatically casts its inputs to the\n    340     # layer's compute_dtype.\n\n/opt/conda/lib/python3.7/site-packages/tensorflow/python/keras/engine/base_layer.py in _set_dtype_policy(self, dtype)\n   1986       self._dtype_policy = dtype\n   1987     elif isinstance(dtype, dict):\n-&gt; 1988       self._dtype_policy = policy.deserialize(dtype)\n   1989     elif dtype:\n   1990       self._dtype_policy = policy.Policy(dtypes.as_dtype(dtype).name)\n\n/opt/conda/lib/python3.7/site-packages/tensorflow/python/keras/mixed_precision/experimental/policy.py in deserialize(config, custom_objects)\n    628       module_objects=module_objects,\n    629       custom_objects=custom_objects,\n--&gt; 630       printable_module_name='dtype policy')\n\n/opt/conda/lib/python3.7/site-packages/tensorflow/python/keras/utils/generic_utils.py in deserialize_keras_object(identifier, module_objects, custom_objects, printable_module_name)\n    360     config = identifier\n    361     (cls, cls_config) = class_and_config_for_serialized_keras_object(\n--&gt; 362         config, module_objects, custom_objects, printable_module_name)\n    363 \n    364     if hasattr(cls, 'from_config'):\n\n/opt/conda/lib/python3.7/site-packages/tensorflow/python/keras/utils/generic_utils.py in class_and_config_for_serialized_keras_object(config, module_objects, custom_objects, printable_module_name)\n    319   cls = get_registered_object(class_name, custom_objects, module_objects)\n    320   if cls is None:\n--&gt; 321     raise ValueError('Unknown ' + printable_module_name + ': ' + class_name)\n    322 \n    323   cls_config = config['config']\n\nValueError: Unknown dtype policy: PolicyV1\n\n</code></pre>\n<p>My model Training Code:</p>\n<pre><code>import tensorflow as tf\nfrom tensorflow.keras.mixed_precision import experimental as mixed_precision\nfrom tensorflow.keras.layers import BatchNormalization\nfrom tensorflow.keras.regularizers import l1\n\npolicy = mixed_precision.Policy('mixed_bfloat16')\nmixed_precision.set_policy(policy)\nreg = l1(0.001)\n\nwith strategy.scope():\n    base_model = tf.keras.applications.EfficientNetB3(weights=&quot;imagenet&quot;, include_top=False)\n    base_model.trainable = True\n\n    model = tf.keras.Sequential([\n        tf.keras.layers.BatchNormalization(),\n        base_model,\n        BatchNormalization(),\n        tf.keras.layers.LeakyReLU(),\n        tf.keras.layers.GlobalAveragePooling2D(),\n        tf.keras.layers.Dense(256),\n        BatchNormalization(),\n\n        tf.keras.layers.LeakyReLU(),\n        BatchNormalization(),\n\n        tf.keras.layers.Dense(128),\n        BatchNormalization(),\n\n        tf.keras.layers.LeakyReLU(),\n        BatchNormalization(),\n\n        tf.keras.layers.Dropout(0.4),\n        BatchNormalization(),\n\n        tf.keras.layers.Dense(64),\n        BatchNormalization(),\n\n        tf.keras.layers.LeakyReLU(),\n        tf.keras.layers.Dense(32),\n        BatchNormalization(),\n\n        tf.keras.layers.Dropout(0.4),\n\n        tf.keras.layers.LeakyReLU(),\n        tf.keras.layers.Dense(16),\n\n        tf.keras.layers.LeakyReLU(),\n        tf.keras.layers.Dense(8),\n        tf.keras.layers.LeakyReLU(),\n        tf.keras.layers.Dense(len(CLASSES), activation='softmax')\n    ])\n\n    model.compile(\n        optimizer=tf.keras.optimizers.SGD(lr=0.04),\n        loss='sparse_categorical_crossentropy',\n        metrics=['sparse_categorical_accuracy'])\n\nfrom tensorflow.keras.callbacks import ModelCheckpoint, EarlyStopping\n\nearly = EarlyStopping(monitor='val_loss',\n                      mode='min',\n                      patience=5)\nSTEPS_PER_EPOCH = 17118 // BATCH_SIZE\nVALID_STEPS = 4279 // BATCH_SIZE\ncheckpoint_filepath = 'gs://mithil/tmp/checkpoint_temp'\nmodel_checkpoint_callback = tf.keras.callbacks.ModelCheckpoint(\n    filepath=checkpoint_filepath,\n    save_weights_only=True,\n    monitor='val_sparse_categorical_accuracy',\n    mode='max',\n    save_best_only=True)\n\nhistory = model.fit(train_dataset,\n                    steps_per_epoch=STEPS_PER_EPOCH,\n\n                    epochs=25,\n                    validation_data=valid_dataset,\n                    validation_steps=VALID_STEPS, callbacks=[early,model_checkpoint_callback])\nmodel.load_weights(checkpoint_filepath)\n\n</code></pre>\n<p>Inference Code</p>\n<pre><code>import tensorflow as tf\nimport numpy as np\nimport os\nimport pandas as pd\nimport cv2\nfrom collections import Counter\nfrom tensorflow.keras.mixed_precision import experimental as mixed_precision\n\nfrom tensorflow.keras.regularizers import l1\npolicy = mixed_precision.Policy('mixed_bfloat16')\nmixed_precision.set_policy(policy)\nmodel = tf.keras.models.load_model(r&quot;../input/model-for-training/effieceintnettpurandomcrop.h5&quot;)\n\nmodel.summary()\npath = &quot;../input/cassava-leaf-disease-classification/test_images&quot;\n\n</code></pre>\n", "link": "https://stackoverflow.com/questions/65449280/tensorflow-giving-unknow-dtype-policy", "last_activity_date": 1622449077, "question_id": 65449280}, {"body": "<p>I get this Error\n<br></p>\n<pre><code>Traceback (most recent call last):\n  File &quot;.../Python/ok.py&quot;, line 1, in &lt;module&gt;\n    from webbot import Browser\n  File &quot;.../Python/webbot.py&quot;, line 2, in &lt;module&gt;\n    web = webbot.Browser()\nAttributeError: partially initialized module 'webbot' has no attribute 'Browser' (most likely due to a circular import)\n</code></pre>\n<br>\n<br>\n<b>My code is as follows:</b>\n<pre><code>from webbot import Browser\nsite = input(&quot;enter a url: &quot;)\nbrowser = Browser()\nbrowser.go_to(site)\n</code></pre>\n<p>I have installed webbot via pip3 on macOS Terminal (zsh)</p>\n", "link": "https://stackoverflow.com/questions/67769189/how-do-i-fix-this-webbot-error-for-python", "last_activity_date": 1622445636, "question_id": 67769189}, {"body": "<p>I have the following code which connects to a MySQL DB and checks which records are marked as 'active' by a field that has '1' in.</p>\n\n<p>The code then downloads some files using the contents of the <code>vulntype</code> field in the URL for the download.</p>\n\n<p>I think the issue lies with the MySQL query or the for loop to do the downloads.</p>\n\n<p>The code is:-</p>\n\n<pre><code>import requests\nimport os\nimport MySQLdb\nfrom hurry.filesize import size, si\nimport logging\nimport logging.handlers\nfrom logging.config import fileConfig\n\nlogging.handlers = logging.handlers\nfileConfig('data/logging_config.ini')\nlogger = logging.getLogger(\"downloader\")\n\n\nactive_vuln_type = None\n\n\ndef get_active_vuln_sets():\n\n    global active_vuln_type\n    try:\n        logging.info('Connecting to the database...')\n        active_vuln_type = con = MySQLdb.connect(*******)\n        logging.info('Database connected!')\n    except FileNotFoundError as fnf:\n        logging.error(fnf)\n    except MySQLdb.Error as e:\n        logging.error(e)\n    try:\n        logging.info('Getting active vulnerability sets...')\n        cur = con.cursor()\n        active = \"1\"\n        cur.execute(\"\"\"SELECT vulntype FROM vuln_sets WHERE active = %s\"\"\", (active))\n        active_vuln_type = cur.fetchall()\n    except MySQLdb.Error as e:\n        logging.exception(e)\n\n\ndef download():\n    try:\n        logging.info('Downloading vulnerability set files...')\n        for x in active_vuln_type:\n            basepath = os.path.dirname(__file__)\n            filepath = os.path.abspath(os.path.join(basepath, \"..\"))\n            response = requests.get('https://vulners.com/api/'\n                                    'v3/archive/collection/?type=' + x)\n            with open(filepath + '/vuln_files/' + x + '.zip', 'wb') as f:\n                f.write(response.content)\n            filesize = size(os.path.getsize\n                            (filepath + '/vuln_files/'\n                             + x + '.zip'), system=si)\n            files = x + \".zip - \" + str(filesize)\n            logging.info('Downloaded ' + x + '.zip Successfully')\n            logging.info('File details: ' + files)\n    except Exception as e:\n        logging.exception(e)\n</code></pre>\n\n<p>The traceback for this is:-</p>\n\n<pre><code>Traceback (most recent call last):\n  File \"/home/luke/projects/vuln_backend/vuln_backend/download.py\", line 61, in download\n    'v3/archive/collection/?type=' + x)\nTypeError: must be str, not tuple\n</code></pre>\n", "link": "https://stackoverflow.com/questions/46913841/python-mysql-typeerror-must-be-str-not-tuple", "last_activity_date": 1622444763, "question_id": 46913841}, {"body": "<p>I'm using &quot;python requests_html&quot; because I want to get the rendered html source code.\nIn addition, I want to do that via socks5h(Tor) proxy.</p>\n<p>So, I tried to write the following code.\nHowever, once render() function was called, raw ip address is displayed.\nThis seems that render() function doesn't use proxy settings.</p>\n<p>Actually, I tried to connect to tor bbc news (onion domain) using the following code, it failed, because that's not tor network.</p>\n<p>Is there any good idea to render using socks5h proxy?</p>\n<pre><code>from requests_html import HTMLSession\n\nurl = &quot;http://ifconfig.me/ip&quot;\n# url = &quot;https://www.bbcnewsv2vjtpsuy.onion/&quot; # bbc news\nsession = HTMLSession()\n\nproxies = {&quot;http&quot;: &quot;socks5h://localhost:9150&quot;,&quot;https&quot;: &quot;socks5h://localhost:9150&quot;}\nr = session.get(url, proxies=proxies)\ncontent = r.html\nprint(content.text) # Tor\u2019s IP will be displayed \n\ncontent.render()    # rendering for javascript, etc..\nprint(content.text) # Raw IP will be displayed\n</code></pre>\n<p>Error message when trying to access tor bbcnews site:</p>\n<blockquote>\n<p>Traceback (most recent call last):   File &quot;requests_html_01.py&quot;, line\n12, in \ncontent.render()    # rendering for javascript   File &quot;/home/testuser/.local/lib/python3.6/site-packages/requests_html.py&quot;,\nline 598, in render\ncontent, result, page = self.session.loop.run_until_complete(self._async_render(url=self.url,\nscript=script, sleep=sleep, wait=wait, content=self.html,\nreload=reload, scrolldown=scrolldown, timeout=timeout,\nkeep_page=keep_page))   File\n&quot;/usr/lib/python3.6/asyncio/base_events.py&quot;, line 484, in\nrun_until_complete\nreturn future.result()   File &quot;/home/testuser/.local/lib/python3.6/site-packages/requests_html.py&quot;,\nline 512, in _async_render\nawait page.goto(url, options={'timeout': int(timeout * 1000)})   File\n&quot;/home/testuser/.local/lib/python3.6/site-packages/pyppeteer/page.py&quot;,\nline 879, in goto\nraise PageError(result) pyppeteer.errors.PageError: net::ERR_INTERNET_DISCONNECTED at <a href=\"https://www.bbcnewsv2vjtpsuy.onion/\" rel=\"nofollow noreferrer\">https://www.bbcnewsv2vjtpsuy.onion/</a></p>\n</blockquote>\n", "link": "https://stackoverflow.com/questions/67743945/python-requests-html-socks5h-proxy-does-not-work-when-calling-render", "last_activity_date": 1622425527, "question_id": 67743945}, {"body": "<p>i've been trying to make a homework and it requires a loop that recieve two inputs and call different functions who returns certain value, the thing is that everithing is well until i repeat the input instructions and returns 'TypeError: float object is not callable' i mean it worked the first time but the second time don't, it's confussing`</p>\n<pre><code>from sys import exit\n\n\ndef sueldoBruto(valorHora, horaTrabajada):\n\n    return (valorHora * horaTrabajada) * 4\n\ndef descuentos(sueldoBruto):\n\n    dctoParaFiscal = sueldoBruto * 0.09\n\n    dctoPension = sueldoBruto * 0.04\n\n    dctoSalud = sueldoBruto * 0.04\n\n    return dctoParaFiscal + dctoPension + dctoSalud\n\ndef sueldoNeto(sueldoBruto):\n\n    return sueldoBruto - descuentos(sueldoBruto)\n\ndef proviciones(sueldoBruto):\n    prima = sueldoBruto * 8.33 / 100\n    cesantias = sueldoBruto * 8.33 / 100\n    interesCesantias = sueldoBruto * 1 / 100\n    vacaciones = sueldoBruto * 4.17 / 100\n\n    return prima + cesantias + interesCesantias + vacaciones\n\n\nwhile True:\n\n    decision = input('Quiere ingresar un profesor?: ')\n    if decision.lower() == 'si':\n\n        nombre = input('Ingrese nombre completo del docente: ')\n        horas = float(input('Ingrese la cantidad de horas trabajadas por semana: '))\n        valorHoras = float(input('Ingresa el valor de la hora: '))\n\n        if horas &gt; 40:\n            valorHoras = valorHoras * 1.5\n\n        sueldoBruto = sueldoBruto(horas, valorHoras)\n\n        dcto = descuentos(sueldoBruto)\n\n        sueldoNeto = sueldoNeto(sueldoBruto)\n\n        proviciones  = proviciones(sueldoBruto)\n\n        print(f'El sueldo bruto del docente {nombre} es: {sueldoBruto} mensuales')\n        print(f'Los descuentos de parafiscales, salud y pension son:  {dcto} mensuales')\n        print(f'El sueldo neto del docente {nombre} es {sueldoNeto}: mensuales')\n        print(f'Las proviciones por prima, cesantias, interes de cesantias y vacaciones son: {proviciones}')\n    else:\n        exit()\n</code></pre>\n<p>`\nThen it returns something like that</p>\n<pre><code>Quiere ingresar un profesor?: si\nIngrese nombre completo del docente: Emanuel Leal\nIngrese la cantidad de horas trabajadas por semana: 42\nIngresa el valor de la hora: 5000\nEl sueldo bruto del docente Emanuel Leal es: 1260000.0 mensuales\nLos descuentos de parafiscales, salud y pension son:  214200.0 mensuales\nEl sueldo neto del docente Emanuel Leal es 1045800.0: mensuales\nLas proviciones por prima, cesantias, interes de cesantias y vacaciones son: 275058.0\nQuiere ingresar un profesor?: si\nIngrese nombre completo del docente: Ana Julia\nIngrese la cantidad de horas trabajadas por semana: 37\nIngresa el valor de la hora: 5600\nTraceback (most recent call last):\nFile &quot;/home/master/Documentos/proyectos/misiontic/ciclo1/semana5/reto4/reto4.py&quot;, line 43, in &lt;module&gt;\nsueldoBruto = sueldoBruto(horas, valorHoras)\nTypeError: 'float' object is not callable\n</code></pre>\n", "link": "https://stackoverflow.com/questions/67765852/i-cant-repeat-a-loop-because-int-or-float-object-is-not-callable", "last_activity_date": 1622409455, "question_id": 67765852}, {"body": "<p>I'm just trying to do something very basic on my Mac using selenium and I can't even open a webpage. I'm getting an error of :</p>\n\n<pre><code>Traceback (most recent call last):\n  File \"/Users/godsinred/Desktop/InstagramLiker/GmailAccountGenerator.py\", line 10, in &lt;module&gt;\n    driver = webdriver.Chrome()\n  File \"/Library/Frameworks/Python.framework/Versions/3.6/lib/python3.6/site-packages/selenium/webdriver/chrome/webdriver.py\", line 68, in __init__\n    self.service.start()\n  File \"/Library/Frameworks/Python.framework/Versions/3.6/lib/python3.6/site-packages/selenium/webdriver/common/service.py\", line 88, in start\n    os.path.basename(self.path), self.start_error_message)\nselenium.common.exceptions.WebDriverException: Message: 'chromedriver' executable may have wrong permissions. Please see https://sites.google.com/a/chromium.org/chromedriver/home\n</code></pre>\n\n<p>Here is my code below:</p>\n\n<pre><code>from selenium import webdriver\nimport time\n\nlink = \"https://accounts.google.com\"\ndriver = webdriver.Chrome()\ndriver.get(link)\ntime.sleep(5)\n\ndriver.quit()\n</code></pre>\n", "link": "https://stackoverflow.com/questions/49787327/selenium-on-mac-message-chromedriver-executable-may-have-wrong-permissions", "last_activity_date": 1622407799, "question_id": 49787327}, {"body": "<p>When I try to run a Python script from Sublime Text 3, I get a pop-up dialog box that simply says &quot;EOFError()&quot; and nothing else.</p>\n<p>I'm using the SublimeREPL plugin, with some slight modifications to my <code>C:\\Users\\Al\\AppData\\Roaming\\Sublime Text 3\\Packages\\SublimeREPL\\config\\Python\\Main.sublime-menu</code> file (based off this video: <a href=\"https://www.youtube.com/watch?v=wM2LbXCkLDI\" rel=\"nofollow noreferrer\">https://www.youtube.com/watch?v=wM2LbXCkLDI</a> ) so I can get an interactive shell opened in a separate tab that runs the program. The main change I made was adding the &quot;-i&quot; command line argument to the Python interpreter to run the interactive shell after the script finishes.</p>\n<p>This has worked fine before. I'm not sure what changed in my configuration or Python or the SublimeREPL package to make it no longer work.</p>\n<p>Here is my <code>Main.sublime-menu</code> file:</p>\n<pre><code>[\n     {\n        &quot;id&quot;: &quot;tools&quot;,\n        &quot;children&quot;:\n        [{\n            &quot;caption&quot;: &quot;SublimeREPL&quot;,\n            &quot;mnemonic&quot;: &quot;R&quot;,\n            &quot;id&quot;: &quot;SublimeREPL&quot;,\n            &quot;children&quot;:\n            [\n                {&quot;caption&quot;: &quot;Python&quot;,\n                &quot;id&quot;: &quot;Python&quot;,\n\n                 &quot;children&quot;:[\n                    {&quot;command&quot;: &quot;repl_open&quot;,\n                     &quot;caption&quot;: &quot;Python&quot;,\n                     &quot;id&quot;: &quot;repl_python&quot;,\n                     &quot;mnemonic&quot;: &quot;P&quot;,\n                     &quot;args&quot;: {\n                        &quot;type&quot;: &quot;subprocess&quot;,\n                        &quot;encoding&quot;: &quot;utf8&quot;,\n                        &quot;cmd&quot;: [&quot;python&quot;, &quot;-i&quot;, &quot;-u&quot;],\n                        &quot;cwd&quot;: &quot;$file_path&quot;,\n                        &quot;syntax&quot;: &quot;Packages/Python/Python.tmLanguage&quot;,\n                        &quot;external_id&quot;: &quot;python&quot;,\n                        &quot;extend_env&quot;: {&quot;PYTHONIOENCODING&quot;: &quot;utf-8&quot;}\n                        }\n                    },\n                    {&quot;command&quot;: &quot;python_virtualenv_repl&quot;,\n                     &quot;id&quot;: &quot;python_virtualenv_repl&quot;,\n                     &quot;caption&quot;: &quot;Python - virtualenv&quot;},\n                    {&quot;command&quot;: &quot;repl_open&quot;,\n                     &quot;caption&quot;: &quot;Python - PDB current file&quot;,\n                     &quot;id&quot;: &quot;repl_python_pdb&quot;,\n                     &quot;mnemonic&quot;: &quot;D&quot;,\n                     &quot;args&quot;: {\n                        &quot;type&quot;: &quot;subprocess&quot;,\n                        &quot;encoding&quot;: &quot;utf8&quot;,\n                        &quot;cmd&quot;: [&quot;python&quot;, &quot;-i&quot;, &quot;-u&quot;, &quot;-m&quot;, &quot;pdb&quot;, &quot;$file_basename&quot;],\n                        &quot;cwd&quot;: &quot;$file_path&quot;,\n                        &quot;syntax&quot;: &quot;Packages/Python/Python.tmLanguage&quot;,\n                        &quot;external_id&quot;: &quot;python&quot;,\n                        &quot;extend_env&quot;: {&quot;PYTHONIOENCODING&quot;: &quot;utf-8&quot;}\n                        }\n                    },\n                    {&quot;command&quot;: &quot;repl_open&quot;,\n                     &quot;caption&quot;: &quot;Python - RUN current file&quot;,\n                     &quot;id&quot;: &quot;repl_python_run&quot;,\n                     &quot;mnemonic&quot;: &quot;R&quot;,\n                     &quot;args&quot;: {\n                        &quot;type&quot;: &quot;subprocess&quot;,\n                        &quot;encoding&quot;: &quot;utf8&quot;,\n                        &quot;cmd&quot;: [&quot;python&quot;, &quot;-i&quot;, &quot;-u&quot;, &quot;$file_basename&quot;],\n                        &quot;cwd&quot;: &quot;$file_path&quot;,\n                        &quot;syntax&quot;: &quot;Packages/Python/Python.tmLanguage&quot;,\n                        &quot;external_id&quot;: &quot;python&quot;,\n                        &quot;extend_env&quot;: {&quot;PYTHONIOENCODING&quot;: &quot;utf-8&quot;}\n                        }\n                    },\n                    {&quot;command&quot;: &quot;repl_open&quot;,\n                     &quot;caption&quot;: &quot;Python - IPython&quot;,\n                     &quot;id&quot;: &quot;repl_python_ipython&quot;,\n                     &quot;mnemonic&quot;: &quot;I&quot;,\n                     &quot;args&quot;: {\n                        &quot;type&quot;: &quot;subprocess&quot;,\n                        &quot;encoding&quot;: &quot;utf8&quot;,\n                        &quot;autocomplete_server&quot;: true,\n                        &quot;cmd&quot;: {\n                            &quot;osx&quot;: [&quot;python&quot;, &quot;-u&quot;, &quot;${packages}/SublimeREPL/config/Python/ipy_repl.py&quot;],\n                            &quot;linux&quot;: [&quot;python&quot;, &quot;-u&quot;, &quot;${packages}/SublimeREPL/config/Python/ipy_repl.py&quot;],\n                            &quot;windows&quot;: [&quot;python&quot;, &quot;-u&quot;, &quot;${packages}/SublimeREPL/config/Python/ipy_repl.py&quot;]\n                        },\n                        &quot;cwd&quot;: &quot;$file_path&quot;,\n                        &quot;syntax&quot;: &quot;Packages/Python/Python.tmLanguage&quot;,\n                        &quot;external_id&quot;: &quot;python&quot;,\n                        &quot;extend_env&quot;: {\n                            &quot;PYTHONIOENCODING&quot;: &quot;utf-8&quot;,\n                            &quot;SUBLIMEREPL_EDITOR&quot;: &quot;$editor&quot;\n                        }\n                    }\n                    }\n                ]}\n            ]\n        }]\n    }\n]\n</code></pre>\n<p>UPDATE: When I look at the Sublime Text console, it shows this error after I tried to run a Python script:</p>\n<pre><code>Traceback (most recent call last):\n  File &quot;C:\\Users\\Al\\AppData\\Roaming\\Sublime Text 3\\Packages\\SublimeREPL\\sublimerepl.py&quot;, line 495, in open\n    rv = ReplView(view, r, syntax, repl_restart_args)\n  File &quot;C:\\Users\\Al\\AppData\\Roaming\\Sublime Text 3\\Packages\\SublimeREPL\\sublimerepl.py&quot;, line 186, in __init__\n    self._history = PersistentHistory(self.external_id)\n  File &quot;C:\\Users\\Al\\AppData\\Roaming\\Sublime Text 3\\Packages\\SublimeREPL\\sublimerepl.py&quot;, line 140, in __init__\n    self._db.create(&quot;external_id&quot;, &quot;command&quot;, &quot;ts&quot;, mode=&quot;open&quot;)\n  File &quot;C:\\Users\\Al\\AppData\\Roaming\\Sublime Text 3\\Packages\\SublimeREPL\\repllibs\\PyDbLite.py&quot;, line 193, in create\n    return self.open()\n  File &quot;C:\\Users\\Al\\AppData\\Roaming\\Sublime Text 3\\Packages\\SublimeREPL\\repllibs\\PyDbLite.py&quot;, line 246, in open\n    self.fields = pickle.load(_in)\nEOFError\nerror: EOFError()\n</code></pre>\n<p>I tried uninstalling and reinstalling SublimeRepl, then restarting Sublime Text, but I get the same error message.</p>\n<p>I did some debugging, and found the <code>_in</code> was a file object of <code>C:\\Users\\Al\\AppData\\Roaming\\Sublime Text 3\\Packages\\User\\.SublimeREPLHistory\\python.db</code>, an 819kb file. I tried deleting it (backing it up to another folder first) and restarting Sublime Text. This seemed to have worked! I guess somehow some null character was written to the history file? It works now. Thanks to MattDMo for pointing me to the Sublime Text console where I could  find the error message.</p>\n", "link": "https://stackoverflow.com/questions/67710502/sublime-text-3-shows-eoferror-when-i-try-to-run-python-scripts-with-sublimerep", "last_activity_date": 1622405747, "question_id": 67710502}, {"body": "<p>my file looks like that:</p>\n<pre><code>|#tail |head   |edge_weight|edge_type                                   |\n|Q8TBF5|Q9UKB1 |3.11133e-01|MI:0004 (affinity chromatography technology)|\n|Q8TBF4|QQ15696|2.01461e-01|MI:0401 (biochemical)                       |\n|Q8TBF4|Q15696 |3.11133e-01|MI:0004 (affinity chromatography technology)|\n</code></pre>\n<p>I want to remove lines that have 'MI:0004 (affinity chromatography technology)' and save the other line in another file also I want to change the format to be some thing like that:</p>\n<pre><code>|#Tail|head    |edge_weight|edge_type            |\n|Q8TBF4|QQ15696|0.201461   |MI:0401 (biochemical)|\n</code></pre>\n<p>note that changed the original edge_weight to float but i get error when i run my script.</p>\n<p>My script:</p>\n<pre><code>from math import log\nfile_path_in_2 = 'D:/Courses/Bioinformatics Diploma/Programming to bioinformatics/Assignments/Assignment_03/PathLinker_PPI.txt'\nfile_in_2 = open(file_path_in_2, 'r')\nfile_path_out_2 = 'D:/Courses/Bioinformatics Diploma/Programming to bioinformatics/Assignments/Assignment_03/PathLinker_PPI_others.txt'\nfile_out_2 = open(file_path_out_2, 'w')\n\nfile_out_2.write('#tail|head\\tedge_weight\\tedge_type\\n')\nfor line in file_in_2:\n     if 'MI:0004 (affinity chromatography technology)' not in line:\n         line_items = line.split('\\t')\n         edge_weight = float(line_items[2])\n         edge_weight = 1 - (edge_weight)\n         new_string = '%s|%s\\t%f\\t%s' %(line_items[0], line_items[1], edge_weight, line_items[3])\n         file_out_2.write(new_string)\nfile_out_2.close()\nfile_in_2.close()\n</code></pre>\n<p>I get this error:</p>\n<pre><code>Traceback (most recent call last):\n  File &quot;E:\\CIT656\\pythonProjects\\CIT656_Spring21\\Assignment_03.py&quot;, line 29, in &lt;module&gt;\n    edge_weight = float(line_items[2])\nValueError: could not convert string to float: 'edge_weight'\n\nProcess finished with exit code 1\n</code></pre>\n", "link": "https://stackoverflow.com/questions/67763930/script-to-remove-lines-that-have-same-string-at-the-end-of-the-line-and-save-the", "last_activity_date": 1622398330, "question_id": 67763930}, {"body": "<p>in practicing using sqlite3 with django, I've created a single row via the Django Shell:</p>\n<pre><code># Import our flight model\nIn [1]: from flights.models import Flight\n\n# Create a new flight\nIn [2]: f = Flight(origin=&quot;New York&quot;, destination=&quot;London&quot;, duration=415)\n\n# Instert that flight into our database\nIn [3]: f.save()\n\n# Query for all flights stored in the database\nIn [4]: Flight.objects.all()\nOut[4]: &lt;QuerySet [&lt;Flight: Flight object (1)&gt;]&gt;\n</code></pre>\n<p>Now I set a variable called flights to store the query:</p>\n<pre><code># Create a variable called flights to store the results of a query\nIn [7]: flights = Flight.objects.all()\n\n# Displaying all flights\nIn [8]: flights\nOut[8]: &lt;QuerySet [&lt;Flight: 1: New York to London&gt;]&gt;\n\n# Isolating just the first flight\nIn [9]: flight = flights.first()\n</code></pre>\n<p>Now in models.py\nI've done the following:</p>\n<pre><code>class Airport(models.Model):\n    code = models.CharField(max_length=3)\n    city = models.CharField(max_length=64)\n\n    def __str__(self):\n        return f&quot;{self.city} ({self.code})&quot;\n\nclass Flight(models.Model):\n    origin = models.ForeignKey(Airport, on_delete=models.CASCADE, related_name=&quot;departures&quot;)\n    destination = models.ForeignKey(Airport, on_delete=models.CASCADE, related_name=&quot;arrivals&quot;)\n    duration = models.IntegerField()\n\n    def __str__(self):\n        return f&quot;{self.id}: {self.origin} to {self.destination}&quot;\n</code></pre>\n<p>After running Migrations:</p>\n<pre><code># Create New Migrations\npython manage.py makemigration\n\n# Migrate\npython manage.py migrate\n</code></pre>\n<p>I get the following error, because I need to delete my existing flight from New York to London to support the new structure, BUT, I'm not sure how to do this...</p>\n<p>Here is the error:</p>\n<pre><code>python manage.py migrate\nSystem check identified some issues:\n\nWARNINGS:\n?: (urls.W005) URL namespace 'flights' isn't unique. You may not be able to \nreverse all URLs in this namespace    \nOperations to perform:\n  Apply all migrations: admin, auth, contenttypes, flights, sessions        \nRunning migrations:\n  Applying flights.0002_auto_20210530_1202...Traceback (most recent call last):\n  File &quot;C:\\Users\\kaij\\Documents\\cs50\\airline\\manage.py&quot;, line 22, in &lt;module&gt;\n    main()\n  File &quot;C:\\Users\\kaij\\Documents\\cs50\\airline\\manage.py&quot;, line 18, in main   \n    execute_from_command_line(sys.argv)\n  File &quot;C:\\Users\\kaij\\AppData\\Local\\Programs\\Python\\Python39\\lib\\site-packages\\django\\core\\management\\__init__.py&quot;, line 419, in execute_from_command_line\n    utility.execute()\n  File &quot;C:\\Users\\kaij\\AppData\\Local\\Programs\\Python\\Python39\\lib\\site-packages\\django\\core\\management\\__init__.py&quot;, line 413, in execute\n    self.fetch_command(subcommand).run_from_argv(self.argv)\n  File &quot;C:\\Users\\kaij\\AppData\\Local\\Programs\\Python\\Python39\\lib\\site-packages\\django\\core\\management\\base.py&quot;, line 354, in run_from_argv\n    self.execute(*args, **cmd_options)  File &quot;C:\\Users\\kaij\\AppData\\Local\\Programs\\Python\\Python39\\lib\\site-packages\\django\\core\\management\\base.py&quot;, line 398, in execute\n    output = self.handle(*args, **options)\n  File &quot;C:\\Users\\kaij\\AppData\\Local\\Programs\\Python\\Python39\\lib\\site-packages\\django\\core\\management\\base.py&quot;, line 89, in wrapped\n    res = handle_func(*args, **kwargs)  File &quot;C:\\Users\\kaij\\AppData\\Local\\Programs\\Python\\Python39\\lib\\site-packages\\django\\core\\management\\commands\\migrate.py&quot;, line 244, in handle\n    post_migrate_state = executor.migrate(\n  File &quot;C:\\Users\\kaij\\AppData\\Local\\Programs\\Python\\Python39\\lib\\site-packages\\django\\db\\migrations\\executor.py&quot;, \nline 117, in migrate\n    state = self._migrate_all_forwards(state, plan, full_plan, fake=fake, fake_initial=fake_initial)\n  File &quot;C:\\Users\\kaij\\AppData\\Local\\Programs\\Python\\Python39\\lib\\site-packages\\django\\db\\migrations\\executor.py&quot;, \nline 147, in _migrate_all_forwards    \n    state = self.apply_migration(state, migration, fake=fake, fake_initial=fake_initial)\n  File &quot;C:\\Users\\kaij\\AppData\\Local\\Programs\\Python\\Python39\\lib\\site-packages\\django\\db\\migrations\\executor.py&quot;, \nline 230, in apply_migration\n    migration_recorded = True\n  File &quot;C:\\Users\\kaij\\AppData\\Local\\Programs\\Python\\Python39\\lib\\site-packages\\django\\db\\backends\\sqlite3\\schema.py&quot;, line 35, in __exit__\n    self.connection.check_constraints()\n  File &quot;C:\\Users\\kaij\\AppData\\Local\\Programs\\Python\\Python39\\lib\\site-packages\\django\\db\\backends\\sqlite3\\base.py&quot;, line 353, in check_constraints, line 353, in check_constraints      \n    raise IntegrityError(             w in table 'flights_flight' with primary key '1' has an invalid foreign k\ndjango.db.utils.IntegrityError: The rots_flight.origin_id contains a value 'New Yoesponding value in flights_aiw in table 'flights_flight' with prima value in flights_airport.id.ry key '1' has an invalid foreign key:e&gt; flights_flight.origin_id contains a value 'New York' that does not have a corresponding value in flights_airport.id.\nPS C:\\Users\\kaij\\Documents\\cs50\\airline&gt;\n</code></pre>\n<p>I've tried typing into the Django shell:</p>\n<pre><code>flight.delete\nflight.delete()\n</code></pre>\n<p>And it still does not delete that row\nthanks</p>\n", "link": "https://stackoverflow.com/questions/67763341/how-to-delete-row-of-table-in-sqlite3-using-django-shell", "last_activity_date": 1622392055, "question_id": 67763341}, {"body": "<p>I am trying to mute someone using a role <code>Muted</code>\nThe Code:</p>\n<pre><code>@bot.command()\nasync def mute(ctx, member:commands.MemberConverter):\n    role = discord.utils.find(lambda r: r.name == 'Muted', ctx.guild.roles)\n    await member.edit(roles=[role])\n</code></pre>\n<p>But I get this weird error:</p>\n<pre><code>Ignoring exception in command mute:\nTraceback (most recent call last):\n  File &quot;C:\\Users\\gathi\\AppData\\Local\\Programs\\Python\\Python39\\lib\\site-packages\\discord\\ext\\commands\\core.py&quot;, line 85, in wrapped\n    ret = await coro(*args, **kwargs)\n  File &quot;C:\\Users\\gathi\\Vscode\\Discord_Bot\\tutorial.py&quot;, line 61, in mute\n    await member.edit(roles=[role]) # 848410518154117130\n  File &quot;C:\\Users\\gathi\\AppData\\Local\\Programs\\Python\\Python39\\lib\\site-packages\\discord\\member.py&quot;, line 681, in edit\n    await http.edit_member(guild_id, self.id, reason=reason, **payload)\n  File &quot;C:\\Users\\gathi\\AppData\\Local\\Programs\\Python\\Python39\\lib\\site-packages\\discord\\http.py&quot;, line 248, in request\n    raise Forbidden(r, data)\ndiscord.errors.Forbidden: 403 Forbidden (error code: 50013): Missing Permissions\n\nThe above exception was the direct cause of the following exception:\n\nTraceback (most recent call last):\n  File &quot;C:\\Users\\gathi\\AppData\\Local\\Programs\\Python\\Python39\\lib\\site-packages\\discord\\ext\\commands\\bot.py&quot;, line 939, in invoke\n    await ctx.command.invoke(ctx)\n  File &quot;C:\\Users\\gathi\\AppData\\Local\\Programs\\Python\\Python39\\lib\\site-packages\\discord\\ext\\commands\\core.py&quot;, line 863, in invoke\n    await injected(*ctx.args, **ctx.kwargs)\n  File &quot;C:\\Users\\gathi\\AppData\\Local\\Programs\\Python\\Python39\\lib\\site-packages\\discord\\ext\\commands\\core.py&quot;, line 94, in wrapped\n    raise CommandInvokeError(exc) from exc\ndiscord.ext.commands.errors.CommandInvokeError: Command raised an exception: Forbidden: 403 Forbidden (error code: 50013): Missing Permissions\n</code></pre>\n<p>I don't understand what to do.</p>\n<p>Here is the perms of the bot:\n<a href=\"https://i.stack.imgur.com/lroXO.png\" rel=\"nofollow noreferrer\">The bots perms</a></p>\n", "link": "https://stackoverflow.com/questions/67758195/discord-py-how-to-assign-someone-a-role", "last_activity_date": 1622391577, "question_id": 67758195}, {"body": "<p>I am new to dynamodb trying to get data from dynamodb.</p>\n\n<p><a href=\"https://i.stack.imgur.com/GVoXN.jpg\" rel=\"noreferrer\">This is my table with \"topic\" as a primary hash key</a></p>\n\n<p>my python code</p>\n\n<pre><code>import boto3 \nfrom boto3 import dynamodb \n\nfrom boto3.session import Session\n\nfrom boto3.dynamodb.conditions import Key, Attr\n\n\ndynamodb_session = Session(aws_access_key_id='XXXXXXXXXXXXXXX',\n          aws_secret_access_key='XXXXXXXXXXXXXXXXXXXXXXXXXXXX',\n          region_name='us-east-1')\n\ndynamodb = dynamodb_session.resource('dynamodb')\n\ntable=dynamodb.Table('Garbage_collector_table')\n\nmy_topic = \"$aws/things/garbage_collector_thing/shadow/update/accepted\"\n\nresponse = table.get_item(TableName='Garbage_collector_table', Key={'topic':my_topic})\n\nfor res in response: \n    print \"result \",res\n</code></pre>\n\n<p>I am getting the following error</p>\n\n<pre><code>Traceback (most recent call last):\n File \"get-data-dynamodb-boto3.py\", line 19, in &lt;module&gt;\n    response = table.get_item(TableName='Garbage_collector_table', Key={'topic': my_topic})   File\n \"/usr/local/lib/python2.7/dist-packages/boto3/resources/factory.py\",\n line 518, in do_action\n     response = action(self, *args, **kwargs)   File \"/usr/local/lib/python2.7/dist-packages/boto3/resources/action.py\",\n line 83, in __call__\n     response = getattr(parent.meta.client, operation_name)(**params)   File \"/usr/local/lib/python2.7/dist-packages/botocore/client.py\", line\n 258, in _api_call\n     return self._make_api_call(operation_name, kwargs)   File /usr/local/lib/python2.7/dist-packages/botocore/client.py\", line 548,\n in _make_api_call\n     raise ClientError(parsed_response, operation_name)\n</code></pre>\n\n<blockquote>\n  <p>botocore.exceptions.ClientError: An error occurred\n  (ValidationException) when calling the GetItem operation: The provided\n  key element does not match the schema</p>\n</blockquote>\n\n<p>am I missing anything in my code?</p>\n", "link": "https://stackoverflow.com/questions/37589254/not-able-to-get-item-from-aws-dynamodb-using-python", "last_activity_date": 1622389314, "question_id": 37589254}, {"body": "<p>I'm trying to use custom wrappers/decorators in Python, and I'd like to declare one <strong>inside</strong> a class, so that I could for instance print a snapshot of the attributes. I've tried things from <a href=\"https://stackoverflow.com/q/11740626/5018771\">this question</a> with no success.</p>\n\n<hr>\n\n<p>Here is what I'd like to do (NB: this code doesn't work, I explain what happens below)</p>\n\n<pre><code>class TestWrapper():\n    def __init__(self, a, b):\n        self.a = a\n        self.b = b\n        self.c = 0\n\n    def enter_exit_info(self, func):\n        def wrapper(*arg, **kw):\n            print '-- entering', func.__name__\n            print '-- ', self.__dict__\n            res = func(*arg, **kw)\n            print '-- exiting', func.__name__\n            print '-- ', self.__dict__\n            return res\n        return wrapper\n\n    @enter_exit_info\n    def add_in_c(self):\n        self.c = self.a + self.b\n        print self.c\n\n    @enter_exit_info\n    def mult_in_c(self):\n        self.c = self.a * self.b\n        print self.c\n\n\nif __name__ == '__main__':\n    t = TestWrapper(2, 3)\n    t.add_in_c()\n    t.mult_in_c()\n</code></pre>\n\n<p>The expected output is :</p>\n\n<pre><code>-- entering add_in_c\n-- {'a': 2, 'b': 3, 'c': 0}\n5\n-- exiting add_in_c\n-- {'a': 2, 'b': 3, 'c': 5}\n-- entering mult_in_c\n-- {'a': 2, 'b': 3, 'c': 5}\n6\n-- exiting mult_in_c\n-- {'a': 2, 'b': 3, 'c': 6}\n</code></pre>\n\n<p>But I this code gives </p>\n\n<pre><code>Traceback (most recent call last):\n  File \"C:\\Users\\cccvag\\workspace\\Test\\src\\module2.py\", line 2, in &lt;module&gt;\n    class TestWrapper():\n  File \"C:\\Users\\cccvag\\workspace\\Test\\src\\module2.py\", line 18, in     TestWrapper\n    @enter_exit_info\nTypeError: enter_exit_info() takes exactly 2 arguments (1 given)\n</code></pre>\n\n<p>And if I try <code>@enter_exit_info(self)</code> or <code>@self.enter_exit_info</code>, I get a <code>NameError</code>. What could I do?</p>\n\n<hr>\n\n<p><strong>EDIT:</strong></p>\n\n<p>I do not need above all to have the decorator <em>physically</em> declared inside the class, as long as it is able to access attributes from an instance of this class. I thought it could only be made by declaring it inside the class, <a href=\"https://stackoverflow.com/a/38524581/5018771\">Rawing's answer</a> proved me wrong.</p>\n", "link": "https://stackoverflow.com/questions/38524332/declaring-decorator-inside-a-class", "last_activity_date": 1622376619, "question_id": 38524332}, {"body": "<p>I have tried to run this code but get an Attribute Error. Any help would be greatly appreciated.</p>\n\n<pre><code>    import cv2\n    import sys\n\n    (major_ver, minor_ver, subminor_ver) = (cv2.__version__).split('.')\n\n    if __name__ == '__main__':\n\n    # Set up tracker.\n    # Instead of MIL, you can also use\n\n    tracker_types = ['BOOSTING', 'MIL','KCF', 'TLD', 'MEDIANFLOW', 'CSRT', 'MOSSE']\n    tracker_type = tracker_types[5]\n\n    if int(minor_ver) &lt; 3:\n        tracker = cv2.cv2.Tracker_create(tracker_type)\n    else:\n        if tracker_type == 'BOOSTING':\n            tracker = cv2.TrackerBoosting_create()\n        if tracker_type == 'MIL':\n            tracker = cv2.TrackerMIL_create()\n        if tracker_type == 'KCF':\n            tracker = cv2.TrackerKCF_create()\n        if tracker_type == 'TLD':\n            tracker = cv2.TrackerTLD_create()\n        if tracker_type == 'MEDIANFLOW':\n            tracker = cv2.TrackerMedianFlow_create()\n        if tracker_type == 'CSRT':\n            tracker = cv2.TrackerCSRT_create()\n        if tracker_type == 'MOSSE':\n            tracker = cv2.TrackerMOSSE_create()\n\n    # Read video\n    video = cv2.VideoCapture(\"./videos/chaplin.mp4\")\n\n    # Exit if video not opened.\n    if not video.isOpened():\n        print(\"Could not open video\")\n        sys.exit()\n\n    # Read first frame.\n    ok, frame = video.read()\n    if not ok:\n        print('Cannot read video file')\n        sys.exit()\n\n    # Define an initial bounding box\n    bbox = (287, 23, 86, 320)\n\n    # Uncomment the line below to select a different bounding box\n    bbox = cv2.selectROI(frame, False)\n\n    # Initialize tracker with first frame and bounding box\n    ok = tracker.init(frame, bbox)\n\n    while True:\n        # Read a new frame\n        ok, frame = video.read()\n        if not ok:\n            break\n\n        # Start timer\n        timer = cv2.getTickCount()\n\n        # Update tracker\n        ok, bbox = tracker.update(frame)\n\n        # Calculate Frames per second (FPS)\n        fps = cv2.getTickFrequency() / (cv2.getTickCount() - timer);\n\n        # Draw bounding box\n        if ok:\n            # Tracking success\n            p1 = (int(bbox[0]), int(bbox[1]))\n            p2 = (int(bbox[0] + bbox[2]), int(bbox[1] + bbox[3]))\n            cv2.rectangle(frame, p1, p2, (255,0,0), 2, 1)\n        else :\n            # Tracking failure\n            cv2.putText(frame, \"Tracking failure detected\", (100,80), cv2.FONT_HERSHEY_SIMPLEX, 0.75,(0,0,255),2)\n\n        # Display tracker type on frame\n        cv2.putText(frame, tracker_type + \" Tracker\", (100,20), cv2.FONT_HERSHEY_SIMPLEX, 0.75, (50,170,50),2);\n\n        # Display FPS on frame\n        cv2.putText(frame, \"FPS : \" + str(int(fps)), (100,50), cv2.FONT_HERSHEY_SIMPLEX, 0.75, (50,170,50), 2);\n\n        # Display result\n        cv2.imshow(\"Tracking\", frame)\n\n        # Exit if ESC pressed\n        k = cv2.waitKey(1) &amp; 0xff\n        if k == 27 : break\n</code></pre>\n\n<p><strong>Output:</strong></p>\n\n<p>Traceback (most recent call last):\n  File \"C:\\Users\\Jatin\\OpenCV-Object-Tracking\\index.py\", line 15, in \n    tracker = cv2.cv2.Tracker_create(tracker_type)\nAttributeError: module 'cv2.cv2' has no attribute 'Tracker_create'</p>\n", "link": "https://stackoverflow.com/questions/58922153/opencv-attributeerror-module-cv2-cv2-has-no-attribute-tracker-create", "last_activity_date": 1622374275, "question_id": 58922153}, {"body": "<pre><code>#program to replace all occurences of a substring with a given substring!!!!\n\ndef replace_string(str,x,y):\n    a = len(x)\n    for i in range(len(str)):\n        if str[i] == x[0]:   \n            end = i+a\n            sub_str = str[i:end]\n            if x == sub_str:\n                str = str[:i] + y + str[end:]\n            else:\n                continue\n        else:\n            continue\n    print (str)\n\nstr = input(&quot;enter a string- &quot;)\nx = input(&quot;Input substring to be deleted- &quot;)\ny = input(&quot;Enter substring to be fit in- &quot;)\nreplace_string(str,x,y)\n</code></pre>\n<p><strong>These are some outputs it gives</strong></p>\n<p>1.</p>\n<pre><code>enter a string- abcabcddabc\nInput substring to be deleted- abc\nEnter substring to be fit in- haha\n</code></pre>\n<p>-&gt;<code>hahahahaddhaha</code></p>\n<p>2.</p>\n<pre><code>enter a string- i am a good boy\nInput substring to be deleted-&lt;space&gt; \nEnter substring to be fit in- &quot;\n</code></pre>\n<p>-&gt;<code>i&quot;am&quot;a&quot;good&quot;boy</code></p>\n<p>But when i put the same string &quot;I am a good boy&quot; but i try to replace good with bad, it gives an error of index out of range but i am not able to understand why this is coming....</p>\n<pre><code>enter a string- i am a good boy\nInput substring to be deleted- good\nEnter substring to be fit in- bad\n</code></pre>\n<pre><code>Traceback (most recent call last):\n  File &quot;f:/----/-----/---------/Fn_replace.py&quot;, line 19, in &lt;module&gt;\n    replace_string(str,x,y)\n  File &quot;f:/----/-----/--------/Fn_replace.py&quot;, line 5, in replace_string\n    if str[i] == x[0]:\nIndexError: string index out of range\n</code></pre>\n<p><strong>PLEASE HELP</strong></p>\n", "link": "https://stackoverflow.com/questions/67760175/i-dont-know-why-this-python-code-for-replacing-all-occurences-of-a-substring-no", "last_activity_date": 1622373140, "question_id": 67760175}, {"body": "<p>When I test the simple app according to tutorial 'AssertionError: 404 != 200' is occured. Can anybody fix this problem? (Project name: <strong>simple_project</strong>, app name inside the project: <strong>pages</strong>)</p>\n\n<p><strong>My app-level urls.py:</strong></p>\n\n<pre><code>from django.urls import path\n\nfrom . import views\n\nurlpatterns = [\n    path('', views.HomePageView.as_view(), name='home'),\n    path('about/', views.AboutPageView.as_view(), name='about'),\n]\n</code></pre>\n\n<p><strong>My app-level views.py:</strong></p>\n\n<pre><code>from django.views.generic import TemplateView\n\nclass HomePageView(TemplateView):\n    template_name = 'home.html'\n\nclass AboutPageView(TemplateView):\n    template_name = 'about.html'\n</code></pre>\n\n<p><strong>My project-level urls.py:</strong></p>\n\n<pre><code>from django.contrib import admin\nfrom django.urls import path, include\n\nurlpatterns = [\n    path('admin/', admin.site.urls),\n    path('', include('pages.urls')),\n]\n</code></pre>\n\n<p><strong>My tests.py:</strong></p>\n\n<pre><code>from django.test import SimpleTestCase\n\nclass SimpleTests(SimpleTestCase):\n    def test_home_page_status_code(self):\n        response = self.client.get('/')\n        self.assertEquals(response.status_code, 200)\n\n    def test_abaout_page_status_code(self):\n        response = self.client.get('about')\n        self.assertEquals(response.status_code, 200)\n</code></pre>\n\n<p><strong>When I test, this error is occured:</strong></p>\n\n<pre><code>FAIL: test_abaout_page_status_code (pages.tests.SimpleTests)\n----------------------------------------------------------------------\nTraceback (most recent call last):\n  File \"C:\\Users\\User\\Dj\\simple\\pages\\tests.py\", line 10, in test_abaout_page_status_code\n    self.assertEquals(response.status_code, 200)\nAssertionError: 404 != 200\n</code></pre>\n", "link": "https://stackoverflow.com/questions/48577781/assertionerror-404-200-in-django-test", "last_activity_date": 1622372050, "question_id": 48577781}, {"body": "<p>I already referred this <a href=\"https://stackoverflow.com/questions/7901402/sqlalchemy-using-wildcards-or-ilike-for-update-statments\">post</a> and this <a href=\"https://stackoverflow.com/questions/20363836/postgresql-ilike-query-with-sqlalchemy\">post</a> but it doesn't help</p>\n<p>I am trying to write the below code</p>\n<pre><code>import psycopg2\nparam_dic = {\n    &quot;host&quot;      : &quot;localhost&quot;,\n    &quot;database&quot;  : &quot;test&quot;,\n    &quot;user&quot;      : &quot;test&quot;,\n    &quot;password&quot;  : &quot;****&quot;\n}\nconn = psycopg2.connect(**param_dic)\ncursor = conn.cursor()\ncursor.execute('select * from test where code in (&quot;0091&quot;,&quot;0092&quot;,&quot;0FY00Z0&quot;,&quot;0FY00Z1&quot;,&quot;0FY00Z2&quot;,&quot;5051&quot;,&quot;5059&quot;)')\n</code></pre>\n<p>In the above <code>cursor execute</code> command, whether I use <code>single quote</code> or <code>double quotes</code> I get the error as shown below</p>\n<blockquote>\n<p>ndefinedColumn                           Traceback (most recent call\nlast)  in \n----&gt; 1 cursor.execute('select * from test where code in\n(&quot;0091&quot;,&quot;0092&quot;,&quot;0FY00Z0&quot;,&quot;0FY00Z1&quot;,&quot;0FY00Z2&quot;,&quot;5051&quot;,&quot;5059&quot;)')</p>\n<p>UndefinedColumn: column &quot;0091&quot; does not exist LINE 1: ...from\ntest where code in (&quot;0091&quot;,&quot;00...</p>\n</blockquote>\n<p>When I change the quotes to <code>single quote</code>, I get the below error</p>\n<blockquote>\n<p>cursor.execute('select * from test where code in\n('0091','0092','0FY00Z0','0FY00Z1','0FY00Z2','5051','5059')')\n^ SyntaxError: invalid token</p>\n</blockquote>\n<p>When I try to use <code>ilike</code> operator, I get the below error</p>\n<pre><code>cursor.execute ('select code from test where long_title ilike '%live%' and long_title ilike '%ransplan%'')\n</code></pre>\n<blockquote>\n<p>NameError: name 'live' is not defined</p>\n</blockquote>\n<p><strong>But all the above query works perfectly fine in my pgadmin postgresql editor. So there is no issue with the SQL in its native form but when I try to use them in python using <code>cursor.execute</code>, I am encountering issues.</strong></p>\n<p>Can you help me with this please?</p>\n", "link": "https://stackoverflow.com/questions/67759781/how-to-use-ilike-and-wildcard-pattern-in-python-psycopg2", "last_activity_date": 1622368831, "question_id": 67759781}, {"body": "<p>I am learning about BS4 and I can't figure out what this code does and why does this code throw out an error like this:</p>\n\n<pre><code>Traceback (most recent call last):\n  File \"/home/ubuntu/workspace/Untitled1.py\", line 17, in &lt;module&gt;\n    for tr in soup.find_all('tr')[3]:\nIndexError: list index out of range\n</code></pre>\n\n<p>The python code using bs4 is:</p>\n\n<pre><code>for tr in soup.find_all('tr')[2]:\n    tds = tr.find_all('td')\n    print(\"value:%s,value 2:%s,value3:%s\" \\\n        (tds[0].text,tds[1].text,tds[2].text))\n</code></pre>\n\n<p>Thank you so much for reading this post. </p>\n", "link": "https://stackoverflow.com/questions/51557902/beautifulsoup4-indexerror-list-index-out-of-range", "last_activity_date": 1622364766, "question_id": 51557902}, {"body": "<p>I am on windows 10 and using python3.9.</p>\n<p>I installed the pagkage\n<em>&gt;python3 -m pip install mysql-connector-python</em></p>\n<p>Now I try to run a simple program</p>\n<pre><code>import mysql.connector\n\nmydb = mysql.connector.connect(\n    host=&quot;localhost&quot;,\n    user=&quot;root&quot;,\n    password=&quot;&quot;,\n    database=&quot;pythonDB&quot;\n)\nmycursor = mydb.cursor()\n\n\nmycursor.execute(&quot;SELECT * FORM customers&quot;)\n\nmyresult = mycursor.fetchall()\n\nfor x in myresult:\n    print(x)\n\n</code></pre>\n<p>I am getting the following error when running\n<em>&gt;python3 select.py</em></p>\n<p>Traceback (most recent call last):\nFile &quot;G:\\Python_w3school\\mysql\\select.py&quot;, line 1, in \nimport mysql.connector\nFile &quot;C:\\Users\\pawar\\AppData\\Local\\Packages\\PythonSoftwareFoundation.Python.3.9_qbz5n2kfra8p0\\LocalCache\\local-packages\\Python39\\site-packages\\mysql\\connector_<em>init</em>_.py&quot;, line 42, in \nimport dns.resolver\nFile &quot;C:\\Users\\pawar\\AppData\\Local\\Packages\\PythonSoftwareFoundation.Python.3.9_qbz5n2kfra8p0\\LocalCache\\local-packages\\Python39\\site-packages\\dns\\resolver.py&quot;, line 20, in \nimport socket\nFile &quot;C:\\Program Files\\WindowsApps\\PythonSoftwareFoundation.Python.3.9_3.9.1520.0_x64__qbz5n2kfra8p0\\lib\\socket.py&quot;, line 54, in \nimport os, sys, io, selectors\nFile &quot;C:\\Program Files\\WindowsApps\\PythonSoftwareFoundation.Python.3.9_3.9.1520.0_x64__qbz5n2kfra8p0\\lib\\selectors.py&quot;, line 12, in \nimport select\nFile &quot;G:\\Python_w3school\\mysql\\select.py&quot;, line 3, in \nmydb = mysql.connector.connect(\nAttributeError: module 'mysql' has no attribute 'connector'</p>\n", "link": "https://stackoverflow.com/questions/67668612/getting-attributeerror-module-mysql-has-no-attribute-connector-in-python", "last_activity_date": 1622361970, "question_id": 67668612}, {"body": "<h2>What I want to do</h2>\n\n<p>I have a python script that imports some modules like <code>pyodbc</code>, and I'm trying to run the script as a job in SQL Server Agent. </p>\n\n<h2>Background</h2>\n\n<ul>\n<li>The SQL Server is on a different server</li>\n<li>I've connected to the server with my user account (not the user account that runs the SQL agent job: let's say it's <code>SQLUser</code>) and installed <code>pyodbc</code> on the server (used <code>pip install pyodbc --user</code>)</li>\n<li>I've checked <code>pip list</code>, <code>pip3 list</code>, <code>pip3.7 list</code> and <code>pyodbc</code> is listed in all in the server</li>\n<li>The script runs fine when I run the script in the server from the command prompt</li>\n</ul>\n\n<h2>problem</h2>\n\n<p>When I run the job, it gives me the following error message:</p>\n\n<pre><code>Executed as user: DOMAIN\\SQLUser. Traceback (most recent call last): File \"PathToScript\\script.py\". line 1, in &lt;module&gt; import pyodbc ModuleNotFoundError: No module named 'pyodbc'. \n</code></pre>\n\n<p>How can I run this script with SQL Server Agent or what else can I do to find the cause of this issue?</p>\n", "link": "https://stackoverflow.com/questions/53888909/modulenotfounderror-when-python-runs-as-a-job-in-sql-server-agent", "last_activity_date": 1622357974, "question_id": 53888909}, {"body": "<pre><code>Traceback (most recent call last):\n  File \"E:\\Program Files\\JetBrains\\PyCharm 2019.1\\helpers\\pydev\\pydevd.py\", line 15, in &lt;module&gt;\n    from _pydevd_bundle.pydevd_constants import IS_JYTH_LESS25, IS_PY34_OR_GREATER, IS_PY36_OR_GREATER, IS_PYCHARM, get_thread_id, \\\n  File \"E:\\Program Files\\JetBrains\\PyCharm 2019.1\\helpers\\pydev\\_pydevd_bundle\\pydevd_constants.py\", line 169, in &lt;module&gt;\n    from _pydev_imps._pydev_saved_modules import thread\n  File \"E:\\Program Files\\JetBrains\\PyCharm 2019.1\\helpers\\pydev\\_pydev_imps\\_pydev_saved_modules.py\", line 21, in &lt;module&gt;\n    import xmlrpc.client as xmlrpclib\n  File \"C:\\Users\\A\\AppData\\Local\\Programs\\Python\\Python37\\lib\\xmlrpc\\client.py\", line 135, in &lt;module&gt;\n    from decimal import Decimal\n  File \"C:\\Users\\A\\AppData\\Local\\Programs\\Python\\Python37\\lib\\decimal.py\", line 3, in &lt;module&gt;\n    from _decimal import *\nAttributeError: module 'numbers' has no attribute 'Number'\n</code></pre>\n", "link": "https://stackoverflow.com/questions/57230859/why-does-the-pycharm-show-attributeerror-module-numbers-has-no-attribute-num", "last_activity_date": 1622357291, "question_id": 57230859}]